Workbook

Sheet 요약
B2: 장비일람표(도면 이미지) vs 장비선정표 비교 결과 보고
B3: 작성일: 2026-07-09 / 비교대상: ① 업로드 도면 이미지 'LG 시스템에어컨 실내기' 장비일람표(50대) ② 표준 260415 장비선정표 모음_민수.xlsx > LG제품 시트(실내기 71개 모델)
B4: ※ 장비일람표.xlsx는 요청에 따라 비교에서 제외. 도면 측 값은 이미지 판독 기반이며, ★ 표시 행은 원본 CAD에서 재확인 권장.
B6: 1. 비교 통계
B7: 도면 장비일람표 실내기 대수 | C7: =COUNTA(모델별_비교!B4:B53) -> 50 | D7: 대
B8: 모델명 완전 일치 | C8: =COUNTIF(모델별_비교!F:F,"일치") -> 27 | D8: 대
B9: 모델명 표기차이 (R-W ↔ RNW) | C9: =COUNTIF(모델별_비교!F:F,"표기차이*") -> 23 | D9: 대
B10: 선정표에 없는 모델 | C10: =COUNTIF(모델별_비교!F:F,"선정표에 없음") -> 0 | D10: 대
B11: 냉방능력 불일치 | C11: =COUNTIF(모델별_비교!I:I,"불일치") -> 3 | D11: 건
B12: 난방능력 불일치 | C12: =COUNTIF(모델별_비교!L:L,"불일치") -> 4 | D12: 건
B13: 종합판정 일치(모델명·용량 모두 일치) | C13: =COUNTIF(모델별_비교!M:M,"일치") -> 26 | D13: 대
B14: 종합판정 용량 불일치 | C14: =COUNTIF(모델별_비교!M:M,"용량 불일치") -> 6 | D14: 대
B15: 선정표 실내기 중 도면에 없는 모델 | C15: =COUNTIF(선정표_실내기!E3:E73,"도면에 없음") -> 21 | D15: 개
B17: 2. 공통으로 공유하는 부분
B18: · 비교 가능한 공통 항목은 3개: 모델명, 정격 냉방능력(W), 정격 난방능력(W) → 상세는 '항목_비교' 시트
B19: · 도면 실내기 50대 전 모델이 선정표 실내기 목록에 존재 (R-W/RNW 표기차이 감안 시)
B20: · 벽걸이·스탠드·덕트·원형카세트 계열(RNW 표기 27대)은 모델명·용량 대부분 일치
B22: 3. 주요 미스매칭 (요주의)
B23: ① IAC-20C : 도면 난방 3,200W ↔ 선정표 2,200W (RNW0200C2S) ★
B24: ② IAC-32C : 도면 냉방 3,300W ↔ 선정표 3,200W (RNW0320C2S) ★
B25: ③ IAC-52C : 도면 난방 5,800W ↔ 선정표 5,900W (RNW0520C2S) ★
B26: ④ IAC-60G : 도면 냉방 4,000W ↔ 선정표 6,000W (RNW0601G2S) ★
B27: ⑤ IAC-52M : 도면 냉방 4,500/난방 5,500W ↔ 선정표 5,200/5,900W (RNW0520M2S) ★
B28: ⑥ IAC-60B : 도면 난방 6,600W ↔ 선정표 6,800W (RNW0601B2S) ★
B29: ⑦ 모델명 표기: 1WAY·2WAY·4WAY 카세트 23대가 도면에서 'R-W', 선정표는 'RNW' 표기 (동일 모델로 추정)
B30: ⑧ IAC-88T : 장비번호 체계 확인 필요 (R-W0831A2U 8.3kW → 통상 IAC-83T)

Sheet 모델별_비교
A1: 장비일람표(도면 이미지) × 장비선정표 모델별 비교
A2: 도면 값: 업로드 이미지 'LG 시스템에어컨 실내기' 판독 / 선정표 값: 표준 260415 장비선정표 모음_민수.xlsx > LG제품 시트
A3: No | B3: 장비번호 | C3: 분류 | D3: 도면 모델명 | E3: 선정표 매칭 모델명 | F3: 모델명 판정 | G3: 도면 냉방(W) | H3: 선정표 냉방(W) | I3: 냉방 판정 | J3: 도면 난방(W) | K3: 선정표 난방(W) | L3: 난방 판정 | M3: 종합 판정 | N3: 비고
A4: 1 | B4: IAC-20C | C4: 1WAY 카세트 | D4: R-W0200C2S | E4: =IFERROR(VLOOKUP(SUBSTITUTE(D4,"R-W","RNW"),선정표_실내기!$A:$C,1,FALSE()),"선정표에 없음") -> RNW0200C2S | F4: =IF(E4="선정표에 없음","선정표에 없음",IF(D4=E4,"일치","표기차이(R-W↔RNW)")) -> 표기차이(R-W↔RNW) | G4: 2000 | H4: =IF(E4="선정표에 없음","",VLOOKUP(SUBSTITUTE(D4,"R-W","RNW"),선정표_실내기!$A:$C,2,FALSE())) -> 2000 | I4: =IF(H4="","-",IF(G4=H4,"일치","불일치")) -> 일치 | J4: 3200 | K4: =IF(E4="선정표에 없음","",VLOOKUP(SUBSTITUTE(D4,"R-W","RNW"),선정표_실내기!$A:$C,3,FALSE())) -> 2200 | L4: =IF(K4="","-",IF(J4=K4,"일치","불일치")) -> 불일치 | M4: =IF(F4="선정표에 없음","선정표에 없음",IF(OR(I4="불일치",L4="불일치"),"용량 불일치",IF(F4="일치","일치","모델명 표기차이"))) -> 용량 불일치 | N4: ★ 이미지 판독값 - 도면 원본(CAD) 재확인 권장
A5: 2 | B5: IAC-23C | C5: 1WAY 카세트 | D5: R-W0230C2S | E5: =IFERROR(VLOOKUP(SUBSTITUTE(D5,"R-W","RNW"),선정표_실내기!$A:$C,1,FALSE()),"선정표에 없음") -> RNW0230C2S | F5: =IF(E5="선정표에 없음","선정표에 없음",IF(D5=E5,"일치","표기차이(R-W↔RNW)")) -> 표기차이(R-W↔RNW) | G5: 2300 | H5: =IF(E5="선정표에 없음","",VLOOKUP(SUBSTITUTE(D5,"R-W","RNW"),선정표_실내기!$A:$C,2,FALSE())) -> 2300 | I5: =IF(H5="","-",IF(G5=H5,"일치","불일치")) -> 일치 | J5: 2600 | K5: =IF(E5="선정표에 없음","",VLOOKUP(SUBSTITUTE(D5,"R-W","RNW"),선정표_실내기!$A:$C,3,FALSE())) -> 2600 | L5: =IF(K5="","-",IF(J5=K5,"일치","불일치")) -> 일치 | M5: =IF(F5="선정표에 없음","선정표에 없음",IF(OR(I5="불일치",L5="불일치"),"용량 불일치",IF(F5="일치","일치","모델명 표기차이"))) -> 모델명 표기차이
A6: 3 | B6: IAC-32C | C6: 1WAY 카세트 | D6: R-W0320C2S | E6: =IFERROR(VLOOKUP(SUBSTITUTE(D6,"R-W","RNW"),선정표_실내기!$A:$C,1,FALSE()),"선정표에 없음") -> RNW0320C2S | F6: =IF(E6="선정표에 없음","선정표에 없음",IF(D6=E6,"일치","표기차이(R-W↔RNW)")) -> 표기차이(R-W↔RNW) | G6: 3300 | H6: =IF(E6="선정표에 없음","",VLOOKUP(SUBSTITUTE(D6,"R-W","RNW"),선정표_실내기!$A:$C,2,FALSE())) -> 3200 | I6: =IF(H6="","-",IF(G6=H6,"일치","불일치")) -> 불일치 | J6: 3600 | K6: =IF(E6="선정표에 없음","",VLOOKUP(SUBSTITUTE(D6,"R-W","RNW"),선정표_실내기!$A:$C,3,FALSE())) -> 3600 | L6: =IF(K6="","-",IF(J6=K6,"일치","불일치")) -> 일치 | M6: =IF(F6="선정표에 없음","선정표에 없음",IF(OR(I6="불일치",L6="불일치"),"용량 불일치",IF(F6="일치","일치","모델명 표기차이"))) -> 용량 불일치 | N6: ★ 이미지 판독값 - 도면 원본(CAD) 재확인 권장
A7: 4 | B7: IAC-40C | C7: 1WAY 카세트 | D7: R-W0400C2S | E7: =IFERROR(VLOOKUP(SUBSTITUTE(D7,"R-W","RNW"),선정표_실내기!$A:$C,1,FALSE()),"선정표에 없음") -> RNW0400C2S | F7: =IF(E7="선정표에 없음","선정표에 없음",IF(D7=E7,"일치","표기차이(R-W↔RNW)")) -> 표기차이(R-W↔RNW) | G7: 4000 | H7: =IF(E7="선정표에 없음","",VLOOKUP(SUBSTITUTE(D7,"R-W","RNW"),선정표_실내기!$A:$C,2,FALSE())) -> 4000 | I7: =IF(H7="","-",IF(G7=H7,"일치","불일치")) -> 일치 | J7: 4500 | K7: =IF(E7="선정표에 없음","",VLOOKUP(SUBSTITUTE(D7,"R-W","RNW"),선정표_실내기!$A:$C,3,FALSE())) -> 4500 | L7: =IF(K7="","-",IF(J7=K7,"일치","불일치")) -> 일치 | M7: =IF(F7="선정표에 없음","선정표에 없음",IF(OR(I7="불일치",L7="불일치"),"용량 불일치",IF(F7="일치","일치","모델명 표기차이"))) -> 모델명 표기차이
A8: 5 | B8: IAC-52C | C8: 1WAY 카세트 | D8: R-W0520C2S | E8: =IFERROR(VLOOKUP(SUBSTITUTE(D8,"R-W","RNW"),선정표_실내기!$A:$C,1,FALSE()),"선정표에 없음") -> RNW0520C2S | F8: =IF(E8="선정표에 없음","선정표에 없음",IF(D8=E8,"일치","표기차이(R-W↔RNW)")) -> 표기차이(R-W↔RNW) | G8: 5200 | H8: =IF(E8="선정표에 없음","",VLOOKUP(SUBSTITUTE(D8,"R-W","RNW"),선정표_실내기!$A:$C,2,FALSE())) -> 5200 | I8: =IF(H8="","-",IF(G8=H8,"일치","불일치")) -> 일치 | J8: 5800 | K8: =IF(E8="선정표에 없음","",VLOOKUP(SUBSTITUTE(D8,"R-W","RNW"),선정표_실내기!$A:$C,3,FALSE())) -> 5900 | L8: =IF(K8="","-",IF(J8=K8,"일치","불일치")) -> 불일치 | M8: =IF(F8="선정표에 없음","선정표에 없음",IF(OR(I8="불일치",L8="불일치"),"용량 불일치",IF(F8="일치","일치","모델명 표기차이"))) -> 용량 불일치 | N8: ★ 이미지 판독값 - 도면 원본(CAD) 재확인 권장
A9: 6 | B9: IAC-60C | C9: 1WAY 카세트 | D9: R-W0600C2S | E9: =IFERROR(VLOOKUP(SUBSTITUTE(D9,"R-W","RNW"),선정표_실내기!$A:$C,1,FALSE()),"선정표에 없음") -> RNW0600C2S | F9: =IF(E9="선정표에 없음","선정표에 없음",IF(D9=E9,"일치","표기차이(R-W↔RNW)")) -> 표기차이(R-W↔RNW) | G9: 6000 | H9: =IF(E9="선정표에 없음","",VLOOKUP(SUBSTITUTE(D9,"R-W","RNW"),선정표_실내기!$A:$C,2,FALSE())) -> 6000 | I9: =IF(H9="","-",IF(G9=H9,"일치","불일치")) -> 일치 | J9: 6800 | K9: =IF(E9="선정표에 없음","",VLOOKUP(SUBSTITUTE(D9,"R-W","RNW"),선정표_실내기!$A:$C,3,FALSE())) -> 6800 | L9: =IF(K9="","-",IF(J9=K9,"일치","불일치")) -> 일치 | M9: =IF(F9="선정표에 없음","선정표에 없음",IF(OR(I9="불일치",L9="불일치"),"용량 불일치",IF(F9="일치","일치","모델명 표기차이"))) -> 모델명 표기차이
A10: 7 | B10: IAC-72C | C10: 1WAY 카세트 | D10: R-W0720C2S | E10: =IFERROR(VLOOKUP(SUBSTITUTE(D10,"R-W","RNW"),선정표_실내기!$A:$C,1,FALSE()),"선정표에 없음") -> RNW0720C2S | F10: =IF(E10="선정표에 없음","선정표에 없음",IF(D10=E10,"일치","표기차이(R-W↔RNW)")) -> 표기차이(R-W↔RNW) | G10: 7200 | H10: =IF(E10="선정표에 없음","",VLOOKUP(SUBSTITUTE(D10,"R-W","RNW"),선정표_실내기!$A:$C,2,FALSE())) -> 7200 | I10: =IF(H10="","-",IF(G10=H10,"일치","불일치")) -> 일치 | J10: 7200 | K10: =IF(E10="선정표에 없음","",VLOOKUP(SUBSTITUTE(D10,"R-W","RNW"),선정표_실내기!$A:$C,3,FALSE())) -> 7200 | L10: =IF(K10="","-",IF(J10=K10,"일치","불일치")) -> 일치 | M10: =IF(F10="선정표에 없음","선정표에 없음",IF(OR(I10="불일치",L10="불일치"),"용량 불일치",IF(F10="일치","일치","모델명 표기차이"))) -> 모델명 표기차이
A11: 8 | B11: IAC-52G | C11: 2WAY 카세트 | D11: R-W0521G2S | E11: =IFERROR(VLOOKUP(SUBSTITUTE(D11,"R-W","RNW"),선정표_실내기!$A:$C,1,FALSE()),"선정표에 없음") -> RNW0521G2S | F11: =IF(E11="선정표에 없음","선정표에 없음",IF(D11=E11,"일치","표기차이(R-W↔RNW)")) -> 표기차이(R-W↔RNW) | G11: 5200 | H11: =IF(E11="선정표에 없음","",VLOOKUP(SUBSTITUTE(D11,"R-W","RNW"),선정표_실내기!$A:$C,2,FALSE())) -> 5200 | I11: =IF(H11="","-",IF(G11=H11,"일치","불일치")) -> 일치 | J11: 5900 | K11: =IF(E11="선정표에 없음","",VLOOKUP(SUBSTITUTE(D11,"R-W","RNW"),선정표_실내기!$A:$C,3,FALSE())) -> 5900 | L11: =IF(K11="","-",IF(J11=K11,"일치","불일치")) -> 일치 | M11: =IF(F11="선정표에 없음","선정표에 없음",IF(OR(I11="불일치",L11="불일치"),"용량 불일치",IF(F11="일치","일치","모델명 표기차이"))) -> 모델명 표기차이
A12: 9 | B12: IAC-60G | C12: 2WAY 카세트 | D12: R-W0601G2S | E12: =IFERROR(VLOOKUP(SUBSTITUTE(D12,"R-W","RNW"),선정표_실내기!$A:$C,1,FALSE()),"선정표에 없음") -> RNW0601G2S | F12: =IF(E12="선정표에 없음","선정표에 없음",IF(D12=E12,"일치","표기차이(R-W↔RNW)")) -> 표기차이(R-W↔RNW) | G12: 4000 | H12: =IF(E12="선정표에 없음","",VLOOKUP(SUBSTITUTE(D12,"R-W","RNW"),선정표_실내기!$A:$C,2,FALSE())) -> 6000 | I12: =IF(H12="","-",IF(G12=H12,"일치","불일치")) -> 불일치 | J12: 6800 | K12: =IF(E12="선정표에 없음","",VLOOKUP(SUBSTITUTE(D12,"R-W","RNW"),선정표_실내기!$A:$C,3,FALSE())) -> 6800 | L12: =IF(K12="","-",IF(J12=K12,"일치","불일치")) -> 일치 | M12: =IF(F12="선정표에 없음","선정표에 없음",IF(OR(I12="불일치",L12="불일치"),"용량 불일치",IF(F12="일치","일치","모델명 표기차이"))) -> 용량 불일치 | N12: ★ 이미지 판독값 - 도면 원본(CAD) 재확인 권장
A13: 10 | B13: IAC-72G | C13: 2WAY 카세트 | D13: R-W0721G2S | E13: =IFERROR(VLOOKUP(SUBSTITUTE(D13,"R-W","RNW"),선정표_실내기!$A:$C,1,FALSE()),"선정표에 없음") -> RNW0721G2S | F13: =IF(E13="선정표에 없음","선정표에 없음",IF(D13=E13,"일치","표기차이(R-W↔RNW)")) -> 표기차이(R-W↔RNW) | G13: 7200 | H13: =IF(E13="선정표에 없음","",VLOOKUP(SUBSTITUTE(D13,"R-W","RNW"),선정표_실내기!$A:$C,2,FALSE())) -> 7200 | I13: =IF(H13="","-",IF(G13=H13,"일치","불일치")) -> 일치 | J13: 8100 | K13: =IF(E13="선정표에 없음","",VLOOKUP(SUBSTITUTE(D13,"R-W","RNW"),선정표_실내기!$A:$C,3,FALSE())) -> 8100 | L13: =IF(K13="","-",IF(J13=K13,"일치","불일치")) -> 일치 | M13: =IF(F13="선정표에 없음","선정표에 없음",IF(OR(I13="불일치",L13="불일치"),"용량 불일치",IF(F13="일치","일치","모델명 표기차이"))) -> 모델명 표기차이
A14: 11 | B14: IAC-23M | C14: 4WAY 카세트 Mini | D14: R-W0230M2S | E14: =IFERROR(VLOOKUP(SUBSTITUTE(D14,"R-W","RNW"),선정표_실내기!$A:$C,1,FALSE()),"선정표에 없음") -> RNW0230M2S | F14: =IF(E14="선정표에 없음","선정표에 없음",IF(D14=E14,"일치","표기차이(R-W↔RNW)")) -> 표기차이(R-W↔RNW) | G14: 2300 | H14: =IF(E14="선정표에 없음","",VLOOKUP(SUBSTITUTE(D14,"R-W","RNW"),선정표_실내기!$A:$C,2,FALSE())) -> 2300 | I14: =IF(H14="","-",IF(G14=H14,"일치","불일치")) -> 일치 | J14: 2600 | K14: =IF(E14="선정표에 없음","",VLOOKUP(SUBSTITUTE(D14,"R-W","RNW"),선정표_실내기!$A:$C,3,FALSE())) -> 2600 | L14: =IF(K14="","-",IF(J14=K14,"일치","불일치")) -> 일치 | M14: =IF(F14="선정표에 없음","선정표에 없음",IF(OR(I14="불일치",L14="불일치"),"용량 불일치",IF(F14="일치","일치","모델명 표기차이"))) -> 모델명 표기차이
A15: 12 | B15: IAC-32M | C15: 4WAY 카세트 Mini | D15: R-W0320M2S | E15: =IFERROR(VLOOKUP(SUBSTITUTE(D15,"R-W","RNW"),선정표_실내기!$A:$C,1,FALSE()),"선정표에 없음") -> RNW0320M2S | F15: =IF(E15="선정표에 없음","선정표에 없음",IF(D15=E15,"일치","표기차이(R-W↔RNW)")) -> 표기차이(R-W↔RNW) | G15: 3200 | H15: =IF(E15="선정표에 없음","",VLOOKUP(SUBSTITUTE(D15,"R-W","RNW"),선정표_실내기!$A:$C,2,FALSE())) -> 3200 | I15: =IF(H15="","-",IF(G15=H15,"일치","불일치")) -> 일치 | J15: 3600 | K15: =IF(E15="선정표에 없음","",VLOOKUP(SUBSTITUTE(D15,"R-W","RNW"),선정표_실내기!$A:$C,3,FALSE())) -> 3600 | L15: =IF(K15="","-",IF(J15=K15,"일치","불일치")) -> 일치 | M15: =IF(F15="선정표에 없음","선정표에 없음",IF(OR(I15="불일치",L15="불일치"),"용량 불일치",IF(F15="일치","일치","모델명 표기차이"))) -> 모델명 표기차이
A16: 13 | B16: IAC-40M | C16: 4WAY 카세트 Mini | D16: R-W0400M2S | E16: =IFERROR(VLOOKUP(SUBSTITUTE(D16,"R-W","RNW"),선정표_실내기!$A:$C,1,FALSE()),"선정표에 없음") -> RNW0400M2S | F16: =IF(E16="선정표에 없음","선정표에 없음",IF(D16=E16,"일치","표기차이(R-W↔RNW)")) -> 표기차이(R-W↔RNW) | G16: 4000 | H16: =IF(E16="선정표에 없음","",VLOOKUP(SUBSTITUTE(D16,"R-W","RNW"),선정표_실내기!$A:$C,2,FALSE())) -> 4000 | I16: =IF(H16="","-",IF(G16=H16,"일치","불일치")) -> 일치 | J16: 4500 | K16: =IF(E16="선정표에 없음","",VLOOKUP(SUBSTITUTE(D16,"R-W","RNW"),선정표_실내기!$A:$C,3,FALSE())) -> 4500 | L16: =IF(K16="","-",IF(J16=K16,"일치","불일치")) -> 일치 | M16: =IF(F16="선정표에 없음","선정표에 없음",IF(OR(I16="불일치",L16="불일치"),"용량 불일치",IF(F16="일치","일치","모델명 표기차이"))) -> 모델명 표기차이
A17: 14 | B17: IAC-52M | C17: 4WAY 카세트 Mini | D17: R-W0520M2S | E17: =IFERROR(VLOOKUP(SUBSTITUTE(D17,"R-W","RNW"),선정표_실내기!$A:$C,1,FALSE()),"선정표에 없음") -> RNW0520M2S | F17: =IF(E17="선정표에 없음","선정표에 없음",IF(D17=E17,"일치","표기차이(R-W↔RNW)")) -> 표기차이(R-W↔RNW) | G17: 4500 | H17: =IF(E17="선정표에 없음","",VLOOKUP(SUBSTITUTE(D17,"R-W","RNW"),선정표_실내기!$A:$C,2,FALSE())) -> 5200 | I17: =IF(H17="","-",IF(G17=H17,"일치","불일치")) -> 불일치 | J17: 5500 | K17: =IF(E17="선정표에 없음","",VLOOKUP(SUBSTITUTE(D17,"R-W","RNW"),선정표_실내기!$A:$C,3,FALSE())) -> 5900 | L17: =IF(K17="","-",IF(J17=K17,"일치","불일치")) -> 불일치 | M17: =IF(F17="선정표에 없음","선정표에 없음",IF(OR(I17="불일치",L17="불일치"),"용량 불일치",IF(F17="일치","일치","모델명 표기차이"))) -> 용량 불일치 | N17: ★ 이미지 판독값 - 도면 원본(CAD) 재확인 권장
A18: 15 | B18: IAC-40T | C18: 4WAY 카세트 듀얼베인 UVnano | D18: R-W0401A2U | E18: =IFERROR(VLOOKUP(SUBSTITUTE(D18,"R-W","RNW"),선정표_실내기!$A:$C,1,FALSE()),"선정표에 없음") -> RNW0401A2U | F18: =IF(E18="선정표에 없음","선정표에 없음",IF(D18=E18,"일치","표기차이(R-W↔RNW)")) -> 표기차이(R-W↔RNW) | G18: 4000 | H18: =IF(E18="선정표에 없음","",VLOOKUP(SUBSTITUTE(D18,"R-W","RNW"),선정표_실내기!$A:$C,2,FALSE())) -> 4000 | I18: =IF(H18="","-",IF(G18=H18,"일치","불일치")) -> 일치 | J18: 4500 | K18: =IF(E18="선정표에 없음","",VLOOKUP(SUBSTITUTE(D18,"R-W","RNW"),선정표_실내기!$A:$C,3,FALSE())) -> 4500 | L18: =IF(K18="","-",IF(J18=K18,"일치","불일치")) -> 일치 | M18: =IF(F18="선정표에 없음","선정표에 없음",IF(OR(I18="불일치",L18="불일치"),"용량 불일치",IF(F18="일치","일치","모델명 표기차이"))) -> 모델명 표기차이
A19: 16 | B19: IAC-52T | C19: 4WAY 카세트 듀얼베인 UVnano | D19: R-W0521A2U | E19: =IFERROR(VLOOKUP(SUBSTITUTE(D19,"R-W","RNW"),선정표_실내기!$A:$C,1,FALSE()),"선정표에 없음") -> RNW0521A2U | F19: =IF(E19="선정표에 없음","선정표에 없음",IF(D19=E19,"일치","표기차이(R-W↔RNW)")) -> 표기차이(R-W↔RNW) | G19: 5200 | H19: =IF(E19="선정표에 없음","",VLOOKUP(SUBSTITUTE(D19,"R-W","RNW"),선정표_실내기!$A:$C,2,FALSE())) -> 5200 | I19: =IF(H19="","-",IF(G19=H19,"일치","불일치")) -> 일치 | J19: 5900 | K19: =IF(E19="선정표에 없음","",VLOOKUP(SUBSTITUTE(D19,"R-W","RNW"),선정표_실내기!$A:$C,3,FALSE())) -> 5900 | L19: =IF(K19="","-",IF(J19=K19,"일치","불일치")) -> 일치 | M19: =IF(F19="선정표에 없음","선정표에 없음",IF(OR(I19="불일치",L19="불일치"),"용량 불일치",IF(F19="일치","일치","모델명 표기차이"))) -> 모델명 표기차이
A20: 17 | B20: IAC-60T | C20: 4WAY 카세트 듀얼베인 UVnano | D20: R-W0601A2U | E20: =IFERROR(VLOOKUP(SUBSTITUTE(D20,"R-W","RNW"),선정표_실내기!$A:$C,1,FALSE()),"선정표에 없음") -> RNW0601A2U | F20: =IF(E20="선정표에 없음","선정표에 없음",IF(D20=E20,"일치","표기차이(R-W↔RNW)")) -> 표기차이(R-W↔RNW) | G20: 6000 | H20: =IF(E20="선정표에 없음","",VLOOKUP(SUBSTITUTE(D20,"R-W","RNW"),선정표_실내기!$A:$C,2,FALSE())) -> 6000 | I20: =IF(H20="","-",IF(G20=H20,"일치","불일치")) -> 일치 | J20: 6800 | K20: =IF(E20="선정표에 없음","",VLOOKUP(SUBSTITUTE(D20,"R-W","RNW"),선정표_실내기!$A:$C,3,FALSE())) -> 6800 | L20: =IF(K20="","-",IF(J20=K20,"일치","불일치")) -> 일치 | M20: =IF(F20="선정표에 없음","선정표에 없음",IF(OR(I20="불일치",L20="불일치"),"용량 불일치",IF(F20="일치","일치","모델명 표기차이"))) -> 모델명 표기차이
A21: 18 | B21: IAC-72T | C21: 4WAY 카세트 듀얼베인 UVnano | D21: R-W0721A2U | E21: =IFERROR(VLOOKUP(SUBSTITUTE(D21,"R-W","RNW"),선정표_실내기!$A:$C,1,FALSE()),"선정표에 없음") -> RNW0721A2U | F21: =IF(E21="선정표에 없음","선정표에 없음",IF(D21=E21,"일치","표기차이(R-W↔RNW)")) -> 표기차이(R-W↔RNW) | G21: 7200 | H21: =IF(E21="선정표에 없음","",VLOOKUP(SUBSTITUTE(D21,"R-W","RNW"),선정표_실내기!$A:$C,2,FALSE())) -> 7200 | I21: =IF(H21="","-",IF(G21=H21,"일치","불일치")) -> 일치 | J21: 8100 | K21: =IF(E21="선정표에 없음","",VLOOKUP(SUBSTITUTE(D21,"R-W","RNW"),선정표_실내기!$A:$C,3,FALSE())) -> 8100 | L21: =IF(K21="","-",IF(J21=K21,"일치","불일치")) -> 일치 | M21: =IF(F21="선정표에 없음","선정표에 없음",IF(OR(I21="불일치",L21="불일치"),"용량 불일치",IF(F21="일치","일치","모델명 표기차이"))) -> 모델명 표기차이
A22: 19 | B22: IAC-88T | C22: 4WAY 카세트 듀얼베인 UVnano | D22: R-W0831A2U | E22: =IFERROR(VLOOKUP(SUBSTITUTE(D22,"R-W","RNW"),선정표_실내기!$A:$C,1,FALSE()),"선정표에 없음") -> RNW0831A2U | F22: =IF(E22="선정표에 없음","선정표에 없음",IF(D22=E22,"일치","표기차이(R-W↔RNW)")) -> 표기차이(R-W↔RNW) | G22: 8300 | H22: =IF(E22="선정표에 없음","",VLOOKUP(SUBSTITUTE(D22,"R-W","RNW"),선정표_실내기!$A:$C,2,FALSE())) -> 8300 | I22: =IF(H22="","-",IF(G22=H22,"일치","불일치")) -> 일치 | J22: 9300 | K22: =IF(E22="선정표에 없음","",VLOOKUP(SUBSTITUTE(D22,"R-W","RNW"),선정표_실내기!$A:$C,3,FALSE())) -> 9300 | L22: =IF(K22="","-",IF(J22=K22,"일치","불일치")) -> 일치 | M22: =IF(F22="선정표에 없음","선정표에 없음",IF(OR(I22="불일치",L22="불일치"),"용량 불일치",IF(F22="일치","일치","모델명 표기차이"))) -> 모델명 표기차이 | N22: 장비번호 확인 필요(모델 용량 8.3kW → 통상 IAC-83T 기대)
A23: 20 | B23: IAC-100T | C23: 4WAY 카세트 듀얼베인 UVnano | D23: R-W1001A2U | E23: =IFERROR(VLOOKUP(SUBSTITUTE(D23,"R-W","RNW"),선정표_실내기!$A:$C,1,FALSE()),"선정표에 없음") -> RNW1001A2U | F23: =IF(E23="선정표에 없음","선정표에 없음",IF(D23=E23,"일치","표기차이(R-W↔RNW)")) -> 표기차이(R-W↔RNW) | G23: 10000 | H23: =IF(E23="선정표에 없음","",VLOOKUP(SUBSTITUTE(D23,"R-W","RNW"),선정표_실내기!$A:$C,2,FALSE())) -> 10000 | I23: =IF(H23="","-",IF(G23=H23,"일치","불일치")) -> 일치 | J23: 11200 | K23: =IF(E23="선정표에 없음","",VLOOKUP(SUBSTITUTE(D23,"R-W","RNW"),선정표_실내기!$A:$C,3,FALSE())) -> 11200 | L23: =IF(K23="","-",IF(J23=K23,"일치","불일치")) -> 일치 | M23: =IF(F23="선정표에 없음","선정표에 없음",IF(OR(I23="불일치",L23="불일치"),"용량 불일치",IF(F23="일치","일치","모델명 표기차이"))) -> 모델명 표기차이
A24: 21 | B24: IAC-110T | C24: 4WAY 카세트 듀얼베인 UVnano | D24: R-W1101A2U | E24: =IFERROR(VLOOKUP(SUBSTITUTE(D24,"R-W","RNW"),선정표_실내기!$A:$C,1,FALSE()),"선정표에 없음") -> RNW1101A2U | F24: =IF(E24="선정표에 없음","선정표에 없음",IF(D24=E24,"일치","표기차이(R-W↔RNW)")) -> 표기차이(R-W↔RNW) | G24: 11000 | H24: =IF(E24="선정표에 없음","",VLOOKUP(SUBSTITUTE(D24,"R-W","RNW"),선정표_실내기!$A:$C,2,FALSE())) -> 11000 | I24: =IF(H24="","-",IF(G24=H24,"일치","불일치")) -> 일치 | J24: 12400 | K24: =IF(E24="선정표에 없음","",VLOOKUP(SUBSTITUTE(D24,"R-W","RNW"),선정표_실내기!$A:$C,3,FALSE())) -> 12400 | L24: =IF(K24="","-",IF(J24=K24,"일치","불일치")) -> 일치 | M24: =IF(F24="선정표에 없음","선정표에 없음",IF(OR(I24="불일치",L24="불일치"),"용량 불일치",IF(F24="일치","일치","모델명 표기차이"))) -> 모델명 표기차이
A25: 22 | B25: IAC-130T | C25: 4WAY 카세트 듀얼베인 UVnano | D25: R-W1301A2U | E25: =IFERROR(VLOOKUP(SUBSTITUTE(D25,"R-W","RNW"),선정표_실내기!$A:$C,1,FALSE()),"선정표에 없음") -> RNW1301A2U | F25: =IF(E25="선정표에 없음","선정표에 없음",IF(D25=E25,"일치","표기차이(R-W↔RNW)")) -> 표기차이(R-W↔RNW) | G25: 13000 | H25: =IF(E25="선정표에 없음","",VLOOKUP(SUBSTITUTE(D25,"R-W","RNW"),선정표_실내기!$A:$C,2,FALSE())) -> 13000 | I25: =IF(H25="","-",IF(G25=H25,"일치","불일치")) -> 일치 | J25: 14600 | K25: =IF(E25="선정표에 없음","",VLOOKUP(SUBSTITUTE(D25,"R-W","RNW"),선정표_실내기!$A:$C,3,FALSE())) -> 14600 | L25: =IF(K25="","-",IF(J25=K25,"일치","불일치")) -> 일치 | M25: =IF(F25="선정표에 없음","선정표에 없음",IF(OR(I25="불일치",L25="불일치"),"용량 불일치",IF(F25="일치","일치","모델명 표기차이"))) -> 모델명 표기차이
A26: 23 | B26: IAC-145T | C26: 4WAY 카세트 듀얼베인 UVnano | D26: R-W1451A2U | E26: =IFERROR(VLOOKUP(SUBSTITUTE(D26,"R-W","RNW"),선정표_실내기!$A:$C,1,FALSE()),"선정표에 없음") -> RNW1451A2U | F26: =IF(E26="선정표에 없음","선정표에 없음",IF(D26=E26,"일치","표기차이(R-W↔RNW)")) -> 표기차이(R-W↔RNW) | G26: 14500 | H26: =IF(E26="선정표에 없음","",VLOOKUP(SUBSTITUTE(D26,"R-W","RNW"),선정표_실내기!$A:$C,2,FALSE())) -> 14500 | I26: =IF(H26="","-",IF(G26=H26,"일치","불일치")) -> 일치 | J26: 16300 | K26: =IF(E26="선정표에 없음","",VLOOKUP(SUBSTITUTE(D26,"R-W","RNW"),선정표_실내기!$A:$C,3,FALSE())) -> 16300 | L26: =IF(K26="","-",IF(J26=K26,"일치","불일치")) -> 일치 | M26: =IF(F26="선정표에 없음","선정표에 없음",IF(OR(I26="불일치",L26="불일치"),"용량 불일치",IF(F26="일치","일치","모델명 표기차이"))) -> 모델명 표기차이
A27: 24 | B27: IAC-23R | C27: 벽걸이형 | D27: RNW0230R2S | E27: =IFERROR(VLOOKUP(SUBSTITUTE(D27,"R-W","RNW"),선정표_실내기!$A:$C,1,FALSE()),"선정표에 없음") -> RNW0230R2S | F27: =IF(E27="선정표에 없음","선정표에 없음",IF(D27=E27,"일치","표기차이(R-W↔RNW)")) -> 일치 | G27: 2300 | H27: =IF(E27="선정표에 없음","",VLOOKUP(SUBSTITUTE(D27,"R-W","RNW"),선정표_실내기!$A:$C,2,FALSE())) -> 2300 | I27: =IF(H27="","-",IF(G27=H27,"일치","불일치")) -> 일치 | J27: 2600 | K27: =IF(E27="선정표에 없음","",VLOOKUP(SUBSTITUTE(D27,"R-W","RNW"),선정표_실내기!$A:$C,3,FALSE())) -> 2600 | L27: =IF(K27="","-",IF(J27=K27,"일치","불일치")) -> 일치 | M27: =IF(F27="선정표에 없음","선정표에 없음",IF(OR(I27="불일치",L27="불일치"),"용량 불일치",IF(F27="일치","일치","모델명 표기차이"))) -> 일치
A28: 25 | B28: IAC-32R | C28: 벽걸이형 | D28: RNW0320R2S | E28: =IFERROR(VLOOKUP(SUBSTITUTE(D28,"R-W","RNW"),선정표_실내기!$A:$C,1,FALSE()),"선정표에 없음") -> RNW0320R2S | F28: =IF(E28="선정표에 없음","선정표에 없음",IF(D28=E28,"일치","표기차이(R-W↔RNW)")) -> 일치 | G28: 3200 | H28: =IF(E28="선정표에 없음","",VLOOKUP(SUBSTITUTE(D28,"R-W","RNW"),선정표_실내기!$A:$C,2,FALSE())) -> 3200 | I28: =IF(H28="","-",IF(G28=H28,"일치","불일치")) -> 일치 | J28: 3600 | K28: =IF(E28="선정표에 없음","",VLOOKUP(SUBSTITUTE(D28,"R-W","RNW"),선정표_실내기!$A:$C,3,FALSE())) -> 3600 | L28: =IF(K28="","-",IF(J28=K28,"일치","불일치")) -> 일치 | M28: =IF(F28="선정표에 없음","선정표에 없음",IF(OR(I28="불일치",L28="불일치"),"용량 불일치",IF(F28="일치","일치","모델명 표기차이"))) -> 일치
A29: 26 | B29: IAC-40R | C29: 벽걸이형 | D29: RNW0400R2S | E29: =IFERROR(VLOOKUP(SUBSTITUTE(D29,"R-W","RNW"),선정표_실내기!$A:$C,1,FALSE()),"선정표에 없음") -> RNW0400R2S | F29: =IF(E29="선정표에 없음","선정표에 없음",IF(D29=E29,"일치","표기차이(R-W↔RNW)")) -> 일치 | G29: 4000 | H29: =IF(E29="선정표에 없음","",VLOOKUP(SUBSTITUTE(D29,"R-W","RNW"),선정표_실내기!$A:$C,2,FALSE())) -> 4000 | I29: =IF(H29="","-",IF(G29=H29,"일치","불일치")) -> 일치 | J29: 4500 | K29: =IF(E29="선정표에 없음","",VLOOKUP(SUBSTITUTE(D29,"R-W","RNW"),선정표_실내기!$A:$C,3,FALSE())) -> 4500 | L29: =IF(K29="","-",IF(J29=K29,"일치","불일치")) -> 일치 | M29: =IF(F29="선정표에 없음","선정표에 없음",IF(OR(I29="불일치",L29="불일치"),"용량 불일치",IF(F29="일치","일치","모델명 표기차이"))) -> 일치
A30: 27 | B30: IAC-52R | C30: 벽걸이형 | D30: RNW0520R2S | E30: =IFERROR(VLOOKUP(SUBSTITUTE(D30,"R-W","RNW"),선정표_실내기!$A:$C,1,FALSE()),"선정표에 없음") -> RNW0520R2S | F30: =IF(E30="선정표에 없음","선정표에 없음",IF(D30=E30,"일치","표기차이(R-W↔RNW)")) -> 일치 | G30: 5200 | H30: =IF(E30="선정표에 없음","",VLOOKUP(SUBSTITUTE(D30,"R-W","RNW"),선정표_실내기!$A:$C,2,FALSE())) -> 5200 | I30: =IF(H30="","-",IF(G30=H30,"일치","불일치")) -> 일치 | J30: 5900 | K30: =IF(E30="선정표에 없음","",VLOOKUP(SUBSTITUTE(D30,"R-W","RNW"),선정표_실내기!$A:$C,3,FALSE())) -> 5900 | L30: =IF(K30="","-",IF(J30=K30,"일치","불일치")) -> 일치 | M30: =IF(F30="선정표에 없음","선정표에 없음",IF(OR(I30="불일치",L30="불일치"),"용량 불일치",IF(F30="일치","일치","모델명 표기차이"))) -> 일치
A31: 28 | B31: IAC-145P | C31: 스탠드형 | D31: RNW1450P2S | E31: =IFERROR(VLOOKUP(SUBSTITUTE(D31,"R-W","RNW"),선정표_실내기!$A:$C,1,FALSE()),"선정표에 없음") -> RNW1450P2S | F31: =IF(E31="선정표에 없음","선정표에 없음",IF(D31=E31,"일치","표기차이(R-W↔RNW)")) -> 일치 | G31: 14500 | H31: =IF(E31="선정표에 없음","",VLOOKUP(SUBSTITUTE(D31,"R-W","RNW"),선정표_실내기!$A:$C,2,FALSE())) -> 14500 | I31: =IF(H31="","-",IF(G31=H31,"일치","불일치")) -> 일치 | J31: 16300 | K31: =IF(E31="선정표에 없음","",VLOOKUP(SUBSTITUTE(D31,"R-W","RNW"),선정표_실내기!$A:$C,3,FALSE())) -> 16300 | L31: =IF(K31="","-",IF(J31=K31,"일치","불일치")) -> 일치 | M31: =IF(F31="선정표에 없음","선정표에 없음",IF(OR(I31="불일치",L31="불일치"),"용량 불일치",IF(F31="일치","일치","모델명 표기차이"))) -> 일치
A32: 29 | B32: IAC-290P | C32: 스탠드형 | D32: RNW2900P2S | E32: =IFERROR(VLOOKUP(SUBSTITUTE(D32,"R-W","RNW"),선정표_실내기!$A:$C,1,FALSE()),"선정표에 없음") -> RNW2900P2S | F32: =IF(E32="선정표에 없음","선정표에 없음",IF(D32=E32,"일치","표기차이(R-W↔RNW)")) -> 일치 | G32: 29000 | H32: =IF(E32="선정표에 없음","",VLOOKUP(SUBSTITUTE(D32,"R-W","RNW"),선정표_실내기!$A:$C,2,FALSE())) -> 29000 | I32: =IF(H32="","-",IF(G32=H32,"일치","불일치")) -> 일치 | J32: 32600 | K32: =IF(E32="선정표에 없음","",VLOOKUP(SUBSTITUTE(D32,"R-W","RNW"),선정표_실내기!$A:$C,3,FALSE())) -> 32600 | L32: =IF(K32="","-",IF(J32=K32,"일치","불일치")) -> 일치 | M32: =IF(F32="선정표에 없음","선정표에 없음",IF(OR(I32="불일치",L32="불일치"),"용량 불일치",IF(F32="일치","일치","모델명 표기차이"))) -> 일치
A33: 30 | B33: IAC-52B | C33: 덕트형(천장매립) | D33: RNW0521B2S | E33: =IFERROR(VLOOKUP(SUBSTITUTE(D33,"R-W","RNW"),선정표_실내기!$A:$C,1,FALSE()),"선정표에 없음") -> RNW0521B2S | F33: =IF(E33="선정표에 없음","선정표에 없음",IF(D33=E33,"일치","표기차이(R-W↔RNW)")) -> 일치 | G33: 5200 | H33: =IF(E33="선정표에 없음","",VLOOKUP(SUBSTITUTE(D33,"R-W","RNW"),선정표_실내기!$A:$C,2,FALSE())) -> 5200 | I33: =IF(H33="","-",IF(G33=H33,"일치","불일치")) -> 일치 | J33: 6000 | K33: =IF(E33="선정표에 없음","",VLOOKUP(SUBSTITUTE(D33,"R-W","RNW"),선정표_실내기!$A:$C,3,FALSE())) -> 6000 | L33: =IF(K33="","-",IF(J33=K33,"일치","불일치")) -> 일치 | M33: =IF(F33="선정표에 없음","선정표에 없음",IF(OR(I33="불일치",L33="불일치"),"용량 불일치",IF(F33="일치","일치","모델명 표기차이"))) -> 일치
A34: 31 | B34: IAC-60B | C34: 덕트형(천장매립) | D34: RNW0601B2S | E34: =IFERROR(VLOOKUP(SUBSTITUTE(D34,"R-W","RNW"),선정표_실내기!$A:$C,1,FALSE()),"선정표에 없음") -> RNW0601B2S | F34: =IF(E34="선정표에 없음","선정표에 없음",IF(D34=E34,"일치","표기차이(R-W↔RNW)")) -> 일치 | G34: 6000 | H34: =IF(E34="선정표에 없음","",VLOOKUP(SUBSTITUTE(D34,"R-W","RNW"),선정표_실내기!$A:$C,2,FALSE())) -> 6000 | I34: =IF(H34="","-",IF(G34=H34,"일치","불일치")) -> 일치 | J34: 6600 | K34: =IF(E34="선정표에 없음","",VLOOKUP(SUBSTITUTE(D34,"R-W","RNW"),선정표_실내기!$A:$C,3,FALSE())) -> 6800 | L34: =IF(K34="","-",IF(J34=K34,"일치","불일치")) -> 불일치 | M34: =IF(F34="선정표에 없음","선정표에 없음",IF(OR(I34="불일치",L34="불일치"),"용량 불일치",IF(F34="일치","일치","모델명 표기차이"))) -> 용량 불일치 | N34: ★ 이미지 판독값 - 도면 원본(CAD) 재확인 권장
A35: 32 | B35: IAC-72B | C35: 덕트형(천장매립) | D35: RNW0721B2S | E35: =IFERROR(VLOOKUP(SUBSTITUTE(D35,"R-W","RNW"),선정표_실내기!$A:$C,1,FALSE()),"선정표에 없음") -> RNW0721B2S | F35: =IF(E35="선정표에 없음","선정표에 없음",IF(D35=E35,"일치","표기차이(R-W↔RNW)")) -> 일치 | G35: 7200 | H35: =IF(E35="선정표에 없음","",VLOOKUP(SUBSTITUTE(D35,"R-W","RNW"),선정표_실내기!$A:$C,2,FALSE())) -> 7200 | I35: =IF(H35="","-",IF(G35=H35,"일치","불일치")) -> 일치 | J35: 8000 | K35: =IF(E35="선정표에 없음","",VLOOKUP(SUBSTITUTE(D35,"R-W","RNW"),선정표_실내기!$A:$C,3,FALSE())) -> 8000 | L35: =IF(K35="","-",IF(J35=K35,"일치","불일치")) -> 일치 | M35: =IF(F35="선정표에 없음","선정표에 없음",IF(OR(I35="불일치",L35="불일치"),"용량 불일치",IF(F35="일치","일치","모델명 표기차이"))) -> 일치
A36: 33 | B36: IAC-83B | C36: 덕트형(천장매립) | D36: RNW0831B2S | E36: =IFERROR(VLOOKUP(SUBSTITUTE(D36,"R-W","RNW"),선정표_실내기!$A:$C,1,FALSE()),"선정표에 없음") -> RNW0831B2S | F36: =IF(E36="선정표에 없음","선정표에 없음",IF(D36=E36,"일치","표기차이(R-W↔RNW)")) -> 일치 | G36: 8300 | H36: =IF(E36="선정표에 없음","",VLOOKUP(SUBSTITUTE(D36,"R-W","RNW"),선정표_실내기!$A:$C,2,FALSE())) -> 8300 | I36: =IF(H36="","-",IF(G36=H36,"일치","불일치")) -> 일치 | J36: 9300 | K36: =IF(E36="선정표에 없음","",VLOOKUP(SUBSTITUTE(D36,"R-W","RNW"),선정표_실내기!$A:$C,3,FALSE())) -> 9300 | L36: =IF(K36="","-",IF(J36=K36,"일치","불일치")) -> 일치 | M36: =IF(F36="선정표에 없음","선정표에 없음",IF(OR(I36="불일치",L36="불일치"),"용량 불일치",IF(F36="일치","일치","모델명 표기차이"))) -> 일치
A37: 34 | B37: IAC-100B | C37: 덕트형(천장매립) | D37: RNW1001B2S | E37: =IFERROR(VLOOKUP(SUBSTITUTE(D37,"R-W","RNW"),선정표_실내기!$A:$C,1,FALSE()),"선정표에 없음") -> RNW1001B2S | F37: =IF(E37="선정표에 없음","선정표에 없음",IF(D37=E37,"일치","표기차이(R-W↔RNW)")) -> 일치 | G37: 10000 | H37: =IF(E37="선정표에 없음","",VLOOKUP(SUBSTITUTE(D37,"R-W","RNW"),선정표_실내기!$A:$C,2,FALSE())) -> 10000 | I37: =IF(H37="","-",IF(G37=H37,"일치","불일치")) -> 일치 | J37: 11200 | K37: =IF(E37="선정표에 없음","",VLOOKUP(SUBSTITUTE(D37,"R-W","RNW"),선정표_실내기!$A:$C,3,FALSE())) -> 11200 | L37: =IF(K37="","-",IF(J37=K37,"일치","불일치")) -> 일치 | M37: =IF(F37="선정표에 없음","선정표에 없음",IF(OR(I37="불일치",L37="불일치"),"용량 불일치",IF(F37="일치","일치","모델명 표기차이"))) -> 일치
A38: 35 | B38: IAC-110B | C38: 덕트형(천장매립) | D38: RNW1101B2S | E38: =IFERROR(VLOOKUP(SUBSTITUTE(D38,"R-W","RNW"),선정표_실내기!$A:$C,1,FALSE()),"선정표에 없음") -> RNW1101B2S | F38: =IF(E38="선정표에 없음","선정표에 없음",IF(D38=E38,"일치","표기차이(R-W↔RNW)")) -> 일치 | G38: 11000 | H38: =IF(E38="선정표에 없음","",VLOOKUP(SUBSTITUTE(D38,"R-W","RNW"),선정표_실내기!$A:$C,2,FALSE())) -> 11000 | I38: =IF(H38="","-",IF(G38=H38,"일치","불일치")) -> 일치 | J38: 12400 | K38: =IF(E38="선정표에 없음","",VLOOKUP(SUBSTITUTE(D38,"R-W","RNW"),선정표_실내기!$A:$C,3,FALSE())) -> 12400 | L38: =IF(K38="","-",IF(J38=K38,"일치","불일치")) -> 일치 | M38: =IF(F38="선정표에 없음","선정표에 없음",IF(OR(I38="불일치",L38="불일치"),"용량 불일치",IF(F38="일치","일치","모델명 표기차이"))) -> 일치
A39: 36 | B39: IAC-130B | C39: 덕트형(천장매립) | D39: RNW1301B2S | E39: =IFERROR(VLOOKUP(SUBSTITUTE(D39,"R-W","RNW"),선정표_실내기!$A:$C,1,FALSE()),"선정표에 없음") -> RNW1301B2S | F39: =IF(E39="선정표에 없음","선정표에 없음",IF(D39=E39,"일치","표기차이(R-W↔RNW)")) -> 일치 | G39: 13000 | H39: =IF(E39="선정표에 없음","",VLOOKUP(SUBSTITUTE(D39,"R-W","RNW"),선정표_실내기!$A:$C,2,FALSE())) -> 13000 | I39: =IF(H39="","-",IF(G39=H39,"일치","불일치")) -> 일치 | J39: 14600 | K39: =IF(E39="선정표에 없음","",VLOOKUP(SUBSTITUTE(D39,"R-W","RNW"),선정표_실내기!$A:$C,3,FALSE())) -> 14600 | L39: =IF(K39="","-",IF(J39=K39,"일치","불일치")) -> 일치 | M39: =IF(F39="선정표에 없음","선정표에 없음",IF(OR(I39="불일치",L39="불일치"),"용량 불일치",IF(F39="일치","일치","모델명 표기차이"))) -> 일치
A40: 37 | B40: IAC-145B | C40: 덕트형(천장매립) | D40: RNW1451B2S | E40: =IFERROR(VLOOKUP(SUBSTITUTE(D40,"R-W","RNW"),선정표_실내기!$A:$C,1,FALSE()),"선정표에 없음") -> RNW1451B2S | F40: =IF(E40="선정표에 없음","선정표에 없음",IF(D40=E40,"일치","표기차이(R-W↔RNW)")) -> 일치 | G40: 14500 | H40: =IF(E40="선정표에 없음","",VLOOKUP(SUBSTITUTE(D40,"R-W","RNW"),선정표_실내기!$A:$C,2,FALSE())) -> 14500 | I40: =IF(H40="","-",IF(G40=H40,"일치","불일치")) -> 일치 | J40: 16300 | K40: =IF(E40="선정표에 없음","",VLOOKUP(SUBSTITUTE(D40,"R-W","RNW"),선정표_실내기!$A:$C,3,FALSE())) -> 16300 | L40: =IF(K40="","-",IF(J40=K40,"일치","불일치")) -> 일치 | M40: =IF(F40="선정표에 없음","선정표에 없음",IF(OR(I40="불일치",L40="불일치"),"용량 불일치",IF(F40="일치","일치","모델명 표기차이"))) -> 일치
...

Sheet 선정표_실내기
A1: 장비선정표 실내기 모델 목록 (표준 260415 장비선정표 모음_민수.xlsx > LG제품 시트)
A2: 모델명 | B2: 냉방(W) | C2: 난방(W) | D2: 계열(모델 접미) | E2: 도면 기재 여부
A3: RNW0200C2S | B3: 2000 | C3: 2200 | D3: 1WAY 카세트 | E3: =IF(COUNTIF(모델별_비교!$E$4:$E$53,A3)>0,"도면에 있음","도면에 없음") -> 도면에 있음
A4: RNW0230C2S | B4: 2300 | C4: 2600 | D4: 1WAY 카세트 | E4: =IF(COUNTIF(모델별_비교!$E$4:$E$53,A4)>0,"도면에 있음","도면에 없음") -> 도면에 있음
A5: RNW0320C2S | B5: 3200 | C5: 3600 | D5: 1WAY 카세트 | E5: =IF(COUNTIF(모델별_비교!$E$4:$E$53,A5)>0,"도면에 있음","도면에 없음") -> 도면에 있음
A6: RNW0400C2S | B6: 4000 | C6: 4500 | D6: 1WAY 카세트 | E6: =IF(COUNTIF(모델별_비교!$E$4:$E$53,A6)>0,"도면에 있음","도면에 없음") -> 도면에 있음
A7: RNW0520C2S | B7: 5200 | C7: 5900 | D7: 1WAY 카세트 | E7: =IF(COUNTIF(모델별_비교!$E$4:$E$53,A7)>0,"도면에 있음","도면에 없음") -> 도면에 있음
A8: RNW0600C2S | B8: 6000 | C8: 6800 | D8: 1WAY 카세트 | E8: =IF(COUNTIF(모델별_비교!$E$4:$E$53,A8)>0,"도면에 있음","도면에 없음") -> 도면에 있음
A9: RNW0720C2S | B9: 7200 | C9: 7200 | D9: 1WAY 카세트 | E9: =IF(COUNTIF(모델별_비교!$E$4:$E$53,A9)>0,"도면에 있음","도면에 없음") -> 도면에 있음
A10: RNW0201C2S | B10: 2000 | C10: 2200 | D10: 1WAY 카세트 | E10: =IF(COUNTIF(모델별_비교!$E$4:$E$53,A10)>0,"도면에 있음","도면에 없음") -> 도면에 없음
A11: RNW0231C2S | B11: 2300 | C11: 2600 | D11: 1WAY 카세트 | E11: =IF(COUNTIF(모델별_비교!$E$4:$E$53,A11)>0,"도면에 있음","도면에 없음") -> 도면에 없음
A12: RNW0321C2S | B12: 3200 | C12: 3600 | D12: 1WAY 카세트 | E12: =IF(COUNTIF(모델별_비교!$E$4:$E$53,A12)>0,"도면에 있음","도면에 없음") -> 도면에 없음
A13: RNW0401C2S | B13: 4000 | C13: 4500 | D13: 1WAY 카세트 | E13: =IF(COUNTIF(모델별_비교!$E$4:$E$53,A13)>0,"도면에 있음","도면에 없음") -> 도면에 없음
A14: RNW0521C2S | B14: 5200 | C14: 5900 | D14: 1WAY 카세트 | E14: =IF(COUNTIF(모델별_비교!$E$4:$E$53,A14)>0,"도면에 있음","도면에 없음") -> 도면에 없음
... A73: RNW1450S2Y | B73: 14500 | C73: 16300 | D73: 원형 카세트 매립형 | E73: =IF(COUNTIF(모델별_비교!$E$4:$E$53,A73)>0,"도면에 있음","도면에 없음") -> 도면에 있음

Sheet 항목_비교
A1: 항목(컬럼) 단위 비교 — 무엇이 공통이고 무엇이 한쪽에만 있는가
A2: 항목 | B2: 도면 장비일람표 | C2: 장비선정표 | D2: 구분 | E2: 비고
A3: 모델명 | B3: O | C3: O | D3: 공통 | E3: 비교 키 항목. 단, 도면은 일부 'R-W' 표기, 선정표는 'RNW' 표기
A4: 정격 냉방능력(W) | B4: O | C4: O | D4: 공통 | E4: 양쪽 수치 직접 비교 가능
A5: 정격 난방능력(W) | B5: O | C5: O | D5: 공통 | E5: 양쪽 수치 직접 비교 가능
A6: 장비번호(IAC-) | B6: O | C6: X | D6: 도면 전용 | E6: 선정표에는 장비번호 체계 없음
A7: 분류(카세트/덕트 등) | B7: O | C7: △ | D7: 도면 전용 | E7: 선정표는 제품군 소제목으로만 존재(항목 아님)
A8: 수량 | B8: O | C8: X | D8: 도면 전용
A9: 전원(상, 선식, V, Hz) | B9: O | C9: X | D9: 도면 전용
A10: 정격 소비전력(kW) 냉방/난방 | B10: O | C10: X | D10: 도면 전용
A11: 운전전류(A) 냉방/난방 | B11: O | C11: X | D11: 도면 전용
A12: 송풍기 풍량(CMM)/기외정압/정격출력 | B12: O | C12: X | D12: 도면 전용
A13: 제품중량(kg) | B13: O | C13: X | D13: 도면 전용
A14: 배관구경(액관/가스관/드레인) | B14: O | C14: X | D14: 도면 전용
A15: 본체치수 / 반입치수(WxHxD) | B15: O | C15: X | D15: 도면 전용
A16: 몸심선(VCTF-SB) / 전원선(H07RN-F) | B16: O | C16: X | D16: 도면 전용
A17: 누전차단기 규격/수량 | B17: O | C17: X | D17: 도면 전용
A18: 실외기 모델·능력(Multi V Super 등) | B18: X | C18: O | D18: 선정표 전용 | E18: 도면 이미지는 실내기 일람표만 해당
A19: 타 제품군(FCU, All in 1, DOAS, Water5 실외기 등) | B19: X | C19: O | D19: 선정표 전용
A20: 냉난방 시험조건(A/B조건) 주석 | B20: X | C20: O | D20: 선정표 전용
