Workbook
Name All실내기: LG제품!$M$1:$M$27
Name All실외기: LG제품!#REF!,LG제품!$Q$3:$Q$7
Name H실외기: LG제품!$I$65:$I$78
Name LRP_N4608V2: #REF!
Name LRP_N4608V2: #REF!
Name LRP_N4608V2: #REF!
Name LRP_N4608V2: #REF!
Name LRP_N4608V2: #REF!
Name LRP_N4608V2: #REF!
Name LT_C831SH: #REF!
Name LT_C831SH: #REF!
Name LT_C831SH: #REF!
Name LT_C831SH: #REF!
Name LT_C831SH: #REF!
Name LT_C831SH: #REF!
Name Mini실외기: LG제품!$I$3:$I$39
Name M실내기: LG제품!$A$3:$A$271
Name M실내기: LG제품!$A$3:$A$271
Name Sp3실외기: LG제품!$E$3:$E$244
Name Space실외기: LG제품!#REF!
Name Space실외기: LG제품!#REF!
Name W실외기: LG제품!$I$40:$I$64
Name 도아스: LG제품!$A$74:$A$81
Name 도아스실외기동시형: LG제품!$I$80:$I$109
Name 동시형실외기: LG제품!$I$82:$I$109
Name 슈퍼4: LG제품!#REF!
Name 슈퍼4: LG제품!#REF!
Name 슈퍼4: LG제품!#REF!
Name 슈퍼4: LG제품!#REF!
Name 슈퍼4: LG제품!#REF!
Name 슈퍼4: LG제품!#REF!
Name 슈퍼4: LG제품!#REF!
Name 실내기: 'eco-V'!#REF!
Name 실외기: 'eco-V'!#REF!
Name 싱글: LG제품!$Q$89:$Q$145
Name 중대형: LG제품!$Q$11:$Q$50
Name 지열실외기: LG제품!$I$66:$I$78
Name 지열인증실내기: LG제품!$V$2:$V$53
Name 지열인증실외기: LG제품!$Z$3:$Z$11
Name 항온항습기: [1]LG제품!$A$77:$A$82
Name 환기: LG제품!$E$248:$E$267

Sheet LG제품
A1: Multi V 실내기 (EHP) | E1: Multi V Super 실외기 | I1: Multi V S 실외기 (상업용) | M1: All in 1 실내기 (스마트) | Q1: All in 1 실외기 (스마트) | V1: Water5 실내기(인증) | Z1: Water5 실외기(인증)
A2: 모델명 | B2: 냉방(w) | C2: 난방(w) | E2: 모델명 | F2: 냉방(w) | G2: 난방(w) | I2: 모델명 | J2: 냉방(w) | K2: 난방(w) | M2: 모델명 | N2: 냉방(w) | O2: 난방(w) | Q2: 모델명 | R2: 냉방(w) | S2: 난방(w) | V2: 모델명 | W2: 냉방(w) | X2: 난방(w) | Z2: 모델명 | AA2: 냉방(w) | AB2: 난방(w)
A3: RNW0200C2S | B3: 2000 | C3: 2200 | E3: 멀티V 5 슈프림 AI | I3: RPUQ041S2S | J3: 11000 | K3: 0 | M3: 1way 일반형 | Q3: 냉전 (스마트) | V3: RNW0200C2S | W3: 2000 | X3: 2200 | Z3: Water5
A4: RNW0230C2S | B4: 2300 | C4: 2600 | E4: RPUW082X9E | F4: 23300 | G4: 25900 | I4: RPUQ051S2S | J4: 14500 | K4: 0 | M4: MNV0200C2W | N4: 2000 | O4: 0 | Q4: MUV0721A23A | R4: 7200 | S4: 0 | V4: RNW0230C2S | W4: 2300 | X4: 2600 | Z4: RGUW081C9C | AA4: 22400 | AB4: 25200
A5: RNW0320C2S | B5: 3200 | C5: 3600 | E5: RPUW102X9E | F5: 29200 | G5: 32800 | I5: RPUQ061S2S | J5: 17000 | K5: 0 | M5: MNV0230C2W | N5: 2300 | O5: 0 | Q5: MUV0901A24A | R5: 9200 | S5: 0 | V5: RNW0320C2S | W5: 3200 | X5: 3600 | Z5: RGUW101C9C | AA5: 28000 | AB5: 31500
A6: RNW0400C2S | B6: 4000 | C6: 4500 | E6: RPUW122X9E | F6: 34800 | G6: 39200 | I6: RPUQ081S9S | J6: 23000 | K6: 0 | M6: MNV0320C2W | N6: 3200 | O6: 0 | Q6: MUV1101B25A | R6: 11000 | S6: 0 | V6: RNW0400C2S | W6: 4000 | X6: 4500 | Z6: RGUW121C9C | AA6: 33600 | AB6: 37800
A7: RNW0520C2S | B7: 5200 | C7: 5900 | E7: RPUW142X9E | F7: 40600 | G7: 45700 | I7: RPUQ101S9S | J7: 29000 | K7: 0 | M7: MNV0400C2W | N7: 4000 | O7: 0 | Q7: MUV1451S25A | R7: 14500 | S7: 0 | V7: RNW0520C2S | W7: 5200 | X7: 5900 | Z7: RGUW201C9C | AA7: 56000 | AB7: 63000
A8: RNW0600C2S | B8: 6000 | C8: 6800 | E8: RPUW162X9E | F8: 46400 | G8: 52200 | I8: RPUW042S2S | J8: 11000 | K8: 12400 | M8: MNV0520C2W | N8: 5200 | O8: 0 | V8: RNW0600C2S | W8: 6000 | X8: 6800 | Z8: Water4
A9: RNW0720C2S | B9: 7200 | C9: 7200 | E9: RPUW182X9E | F9: 52200 | G9: 58700 | I9: RPUW052S2S | J9: 14500 | K9: 16300 | M9: MNV0600C2W | N9: 6000 | O9: 0 | Q9: 스탠드 | V9: RNW0720C2S | W9: 7200 | X9: 7200 | Z9: RGUW200C9E | AA9: 55800 | AB9: 55500
A10: RNW0201C2S | B10: 2000 | C10: 2200 | E10: RPUW202X9E | F10: 57000 | G10: 63000 | I10: RPUW062S2S | J10: 16000 | K10: 18000 | M10: MNV0720C2W | N10: 7200 | O10: 0 | Q10: 모델명 | R10: 냉방(w) | S10: 난방(w) | V10: RNW0521G2S | W10: 5200 | X10: 5900 | Z10: RGUW240C9C | AA10: 66400 | AB10: 68000
A11: RNW0231C2S | B11: 2300 | C11: 2600 | E11: RPUW222X9E | F11: 64000 | G11: 72000 | I11: RPUW041S9S | J11: 11000 | K11: 12400 | M11: 1way UV Nano | Q11: 1등급 | V11: RNW0601G2S | W11: 6000 | X11: 6800 | Z11: RGUW260C9E | AA11: 71400 | AB11: 73600
A12: RNW0321C2S | B12: 3200 | C12: 3600 | E12: RPUW242X9E | F12: 69600 | G12: 78400 | I12: RPUW051S9S | J12: 14500 | K12: 16300 | M12: MNV0121K2U | N12: 1200 | O12: 0 | Q12: PW052PT2SR | R12: 5200 | S12: 6000 | V12: RNW0721G2S | W12: 7200 | X12: 8100
A13: RNW0401C2S | B13: 4000 | C13: 4500 | E13: RP-W262X9E | F13: 75400 | G13: 84900 | I13: RPUW061S9S | J13: 16000 | K13: 18000 | M13: MNV0161K2U | N13: 1600 | O13: 0 | Q13: PW060PT2SR | R13: 6000 | S13: 7200 | V13: RNW0230M2S | W13: 2300 | X13: 2600
A14: RNW0521C2S | B14: 5200 | C14: 5900 | E14: RP-W282X9E | F14: 81200 | G14: 91400 | I14: RPUW081S9S | J14: 22400 | K14: 25200 | M14: MNV0201K2U | N14: 2000 | O14: 0 | Q14: PW072PT2SR | R14: 7200 | S14: 8500 | V14: RNW0320M2S | W14: 3200 | X14: 3600
A15: RNW0601C2S | B15: 6000 | C15: 6800 | E15: RP-W302X9E | F15: 87000 | G15: 97900 | I15: RPUW101S9S | J15: 28000 | K15: 31500 | M15: MNV0231K2U | N15: 2300 | O15: 0 | Q15: PW083PT2SR | R15: 8300 | S15: 9200 | V15: RNW0400M2S | W15: 4000 | X15: 4500
A16: RNW0721C2S | B16: 7200 | C16: 7200 | E16: RP-W322X9E | F16: 91800 | G16: 102200 | I16: RPUW121S9S | J16: 33600 | K16: 37800 | M16: MNV0201C2U | N16: 2000 | O16: 0 | Q16: PW1100U2HR | R16: 11000 | S16: 13200 | V16: RNW0400T2S | W16: 4000 | X16: 4500
A17: RNW0521G2S | B17: 5200 | C17: 5900 | E17: RP-W342X9E | F17: 97600 | G17: 108700 | I17: 상업용(R32) | M17: MNV0231C2U | N17: 2300 | O17: 0 | Q17: PW1100U9HR | R17: 11000 | S17: 13200 | V17: RNW0520T2S | W17: 5200 | X17: 5900
A18: RNW0601G2S | B18: 6000 | C18: 6800 | E18: RP-W362X9E | F18: 103400 | G18: 115200 | I18: RPUW041S2Z | J18: 11000 | K18: 12400 | M18: MNV0321C2U | N18: 3200 | O18: 0 | Q18: PW1300U2HR | R18: 13000 | S18: 15000 | V18: RNW0600T2S | W18: 6000 | X18: 6800
A19: RNW0721G2S | B19: 7200 | C19: 8100 | E19: RP-W382X9E | F19: 109200 | G19: 121700 | I19: RPUW051S2Z | J19: 14500 | K19: 16300 | M19: MNV0401C2U | N19: 4000 | O19: 0 | Q19: PW1300U9HR | R19: 13000 | S19: 15000 | V19: RNW0720T2S | W19: 7200 | X19: 8100
A20: RNW0230M2S | B20: 2300 | C20: 2600 | E20: RP-W402X9E | F20: 114000 | G20: 126000 | I20: RPUW061S2Z | J20: 16000 | K20: 18000 | M20: MNV0521C2U | N20: 5200 | O20: 0 | Q20: PW1450U9HR | R20: 14500 | S20: 16700 | V20: RNW0830T2S | W20: 8300 | X20: 9300
A21: RNW0320M2S | B21: 3200 | C21: 3600 | E21: RP-W422X9E | F21: 121000 | G21: 135000 | I21: RPUW041S9Z | J21: 11000 | K21: 12400 | M21: MNV0601C2U | N21: 6000 | O21: 0 | Q21: 프리미엄 | V21: RNW1000T2S | W21: 10000 | X21: 11200
A22: RNW0400M2S | B22: 4000 | C22: 4500 | E22: RP-W442X9E | F22: 126600 | G22: 141400 | I22: RPUW051S9Z | J22: 14500 | K22: 16300 | M22: MNV0721C2U | N22: 7200 | O22: 0 | Q22: PW0522R2S | R22: 5200 | S22: 6000 | V22: RNW1100T2S | W22: 11000 | X22: 12400
A23: RNW0520M2S | B23: 5200 | C23: 5900 | E23: RP-W462X9E | F23: 133600 | G23: 150400 | I23: RPUW061S9Z | J23: 16000 | K23: 18000 | M23: 벽걸이 | Q23: PW0603R2C | R23: 6000 | S23: 7200 | V23: RNW1300T2S | W23: 13000 | X23: 14600
A24: RNW0401A2U | B24: 4000 | C24: 4500 | E24: RP-W482X9E | F24: 139200 | G24: 156800 | I24: Multi V S 실외기 (주거용) | M24: MNV0230R2S | N24: 2300 | O24: 0 | Q24: PW0721R2SR | R24: 7200 | S24: 8500 | V24: RNW1450T2S | W24: 14500 | X24: 16300
A25: RNW0521A2U | B25: 5200 | C25: 5900 | E25: 프리미엄 라이트 | I25: 모델명 | J25: 냉방(w) | K25: 난방(w) | M25: MNV0320R2S | N25: 3200 | O25: 0 | Q25: PW0833R2CR | R25: 8300 | S25: 9200 | V25: RNW0230L2S | W25: 2300 | X25: 2600
A26: RNW0601A2U | B26: 6000 | C26: 6800 | E26: RPUW082X9T | F26: 23300 | G26: 25900 | I26: AI 엔진 X | M26: MNV0400R2S | N26: 4000 | O26: 0 | Q26: PW1101T2SR | R26: 11000 | S26: 12400 | V26: RNW0320L2S | W26: 3200 | X26: 3600
A27: RNW0721A2U | B27: 7200 | C27: 8100 | E27: RPUW102X9T | F27: 29200 | G27: 32800 | I27: RPUQ0255A2R | J27: 7200 | K27: 0 | M27: MNV0520R2S | N27: 5200 | O27: 0 | Q27: PW1103T9CR | R27: 11000 | S27: 12400 | V27: RNW0400L2S | W27: 4000 | X27: 4500
A28: RNW0831A2U | B28: 8300 | C28: 9300 | E28: RPUW122X9T | F28: 34800 | G28: 39200 | I28: RPUQ0305A2R | J28: 9200 | K28: 0 | Q28: PW1301T2SR | R28: 13000 | S28: 15000 | V28: RNW0520B2S | W28: 5200 | X28: 5900
A29: RNW1001A2U | B29: 10000 | C29: 11200 | E29: RPUW142X9T | F29: 40600 | G29: 45700 | I29: RPUQ0405B2R | J29: 11000 | K29: 0 | Q29: PW1301T9SR | R29: 13000 | S29: 15000 | V29: RNW0600B2S | W29: 6000 | X29: 6800
A30: RNW1101A2U | B30: 11000 | C30: 12400 | E30: RPUW162X9T | F30: 46400 | G30: 52200 | I30: RPUQ0506S2R | J30: 14500 | K30: 0 | Q30: PW1453T9CR | R30: 14500 | S30: 16300 | V30: RNW0720B2S | W30: 7200 | X30: 8100
A31: RNW1301A2U | B31: 13000 | C31: 14600 | E31: RPUW182X9T | F31: 52200 | G31: 58700 | I31: RPUQ0606S2R | J31: 17000 | K31: 0 | Q31: 프리미엄PLUS | V31: RNW0830B2S | W31: 8300 | X31: 9300
A32: RNW1451A2U | B32: 14500 | C32: 16300 | E32: RPUW202X9T | F32: 57000 | G32: 63000 | I32: RPUQ0802S9R | J32: 23000 | K32: 0 | Q32: PW0520R2SL | R32: 5200 | S32: 6000 | V32: RNW1000B2S | W32: 10000 | X32: 11200
A33: RNW0230L2S | B33: 2300 | C33: 2600 | E33: RP-W222X9T | F33: 64000 | G33: 72000 | I33: RPUQ1002S9R | J33: 29000 | K33: 0 | Q33: PW0600R2SL | R33: 6000 | S33: 7200 | V33: RNW1100B2S | W33: 11000 | X33: 12400
A34: RNW0320L2S | B34: 3200 | C34: 3600 | E34: RP-W242X9T | F34: 69600 | G34: 78400 | I34: AI 엔진 O | Q34: PW0720R2SL | R34: 7200 | S34: 8500 | V34: RNW1300B2S | W34: 13000 | X34: 14600
A35: RNW0400L2S | B35: 4000 | C35: 4500 | E35: RP-W262X9T | F35: 75400 | G35: 84900 | I35: RPUQ0255A2A | J35: 7200 | K35: 0 | Q35: PW0830R2SL | R35: 8300 | S35: 9200 | V35: RNW1450B2S | W35: 14500 | X35: 16300
A36: RNW0521B2S | B36: 5200 | C36: 6000 | E36: RP-W282X9T | F36: 81200 | G36: 91400 | I36: RPUQ0305A2A | J36: 9200 | K36: 0 | Q36: PW1100T2SL | R36: 11000 | S36: 12400 | V36: RNW2300B2S | W36: 23000 | X36: 25900
A37: RNW0601B2S | B37: 6000 | C37: 6800 | E37: RP-W302X9T | F37: 87000 | G37: 97900 | I37: RPUQ0405B2A | J37: 11000 | K37: 0 | Q37: PW1100T9SL | R37: 11000 | S37: 12400 | V37: RNW2900B2S | W37: 29000 | X37: 32600
A38: RNW0721B2S | B38: 7200 | C38: 8000 | E38: RP-W322X9T | F38: 91800 | G38: 102200 | I38: RPUQ0506S2A | J38: 14500 | K38: 0 | Q38: PW1300T2SL | R38: 13000 | S38: 15000 | V38: RNW0230U2S | W38: 2300 | X38: 2600
A39: RNW0831B2S | B39: 8300 | C39: 9300 | E39: RP-W342X9T | F39: 97600 | G39: 108700 | I39: RPUQ0606S2A | J39: 17000 | K39: 0 | Q39: PW1300T9SL | R39: 13000 | S39: 15000 | V39: RNW0320U2S | W39: 3200 | X39: 3600
A40: RNW1001B2S | B40: 10000 | C40: 11200 | E40: RP-W362X9T | F40: 103400 | G40: 115200 | Q40: PW1450T9SL | R40: 14500 | S40: 16300 | V40: RNW0400U2S | W40: 4000 | X40: 4500
...

Sheet eco-V
A1: ▣ 환기 장비선정표
A3: 층 별 | B3: 실 명 | C3: 면적 | D3: 층고 | E3: 체적 | F3: 재실인원에 의한 환기량 | I3: 점유면적에 의한 환기량 | L3: 환기횟수에 의한 환기량 | N3: 장비 번호 | O3: 장비선정
F4: 인원 | G4: 인당필요환기량 | H4: 선정환기량 | I4: 인당점유면적 | J4: 인당필요환기량 | K4: 선정환기량 | L4: 환기횟수 | M4: 선정환기량 | O4: 모델명 | P4: 환기량 | Q4: 수량
C5: ㎡ | D5: m | E5: ㎥ | F5: (인) | G5: (CMH) | H5: (CMH) | I5: (㎡/인) | J5: (CMH) | K5: (CMH) | L5: (N) | M5: (CMH) | P5: (CMH) | Q5: (대)
A6: 지하1층 | B6: 시청각실 | C6: 364 | D6: 3 | E6: =C6*D6 -> 1092 | F6: 0 | G6: 0 | H6: =F6*G6 -> 0 | I6: 5 | J6: 29 | K6: =C6/I6*J6 -> 2111.2 | L6: 0 | M6: =E6*L6 -> 0 | N6: =INDEX($N$20:$N$41,MATCH(O6,$O$20:$O$41,0)) -> 1000 | O6: Z-E1000U2SC | P6: =IF(ISERROR(VLOOKUP(O6,LG제품!$E$248:$F$267,2,0)),,VLOOKUP(O6,LG제품!$E$248:$F$267,2,0)) -> 1000 | Q6: 2
B7: 준비실(위) | C7: 5.4 | D7: 3 | E7: =C7*D7 -> 16.2 | F7: 0 | G7: 0 | H7: =F7*G7 -> 0 | I7: 5 | J7: 29 | K7: =C7/I7*J7 -> 31.32 | L7: 0 | M7: =E7*L7 -> 0
B8: 준비실(아래) | C8: 7.2 | D8: 3 | E8: =C8*D8 -> 21.6 | F8: 0 | G8: 0 | H8: =F8*G8 -> 0 | I8: 5 | J8: 29 | K8: =C8/I8*J8 -> 41.76 | L8: 0 | M8: =E8*L8 -> 0
B9: TOTAL | K9: =SUM(K6:K8) -> 2184.28
A10: 지상1층 | B10: 미술실 | C10: 97.5 | D10: 3 | E10: =C10*D10 -> 292.5 | F10: 0 | G10: 0 | H10: =F10*G10 -> 0 | I10: 3 | J10: 29 | K10: =C10/I10*J10 -> 942.5 | L10: 0 | M10: =E10*L10 -> 0 | N10: =INDEX($N$20:$N$41,MATCH(O10,$O$20:$O$41,0)) -> 1000 | O10: Z-E1000U2SC | P10: =IF(ISERROR(VLOOKUP(O10,LG제품!$E$248:$F$267,2,0)),,VLOOKUP(O10,LG제품!$E$248:$F$267,2,0)) -> 1000 | Q10: 1
B11: TOTAL | K11: =SUM(K10) -> 942.5
B12: 기술실 | C12: 99 | D12: 3 | E12: =C12*D12 -> 297 | F12: 0 | G12: 0 | H12: =F12*G12 -> 0 | I12: 3 | J12: 29 | K12: =C12/I12*J12 -> 957 | L12: 0 | M12: =E12*L12 -> 0 | N12: =INDEX($N$20:$N$41,MATCH(O12,$O$20:$O$41,0)) -> 1000 | O12: Z-E1000U2SC | P12: =IF(ISERROR(VLOOKUP(O12,LG제품!$E$248:$F$267,2,0)),,VLOOKUP(O12,LG제품!$E$248:$F$267,2,0)) -> 1000 | Q12: 1
B13: TOTAL | K13: =SUM(K12) -> 957
B14: 도서실,미디어실 | C14: 188.4 | D14: 3 | E14: =C14*D14 -> 565.2 | F14: 0 | G14: 0 | H14: =F14*G14 -> 0 | I14: 3 | J14: 29 | K14: =C14/I14*J14 -> 1821.2 | L14: 0 | M14: =E14*L14 -> 0 | N14: =INDEX($N$20:$N$41,MATCH(O14,$O$20:$O$41,0)) -> 1000 | O14: Z-E1000U2SC | P14: =IF(ISERROR(VLOOKUP(O14,LG제품!$E$248:$F$267,2,0)),,VLOOKUP(O14,LG제품!$E$248:$F$267,2,0)) -> 1000 | Q14: 2
B15: TOTAL | K15: =SUM(K14) -> 1821.2
Q16: =SUM(Q6:Q15) -> 6
N19: 상업용
N20: 250 | O20: Z-E0250U2SC | P20: =SUMPRODUCT(($O$6:$O$15=O20)*($Q$6:$Q$15)) -> 0
N21: 350 | O21: Z-E0350U2SC | P21: =SUMPRODUCT(($O$6:$O$15=O21)*($Q$6:$Q$15)) -> 0
N22: 500 | O22: Z-E0500U2SC | P22: =SUMPRODUCT(($O$6:$O$15=O22)*($Q$6:$Q$15)) -> 0
N23: 800 | O23: Z-E0800U2SC | P23: =SUMPRODUCT(($O$6:$O$15=O23)*($Q$6:$Q$15)) -> 0
N24: 1000 | O24: Z-E1000U2SC | P24: =SUMPRODUCT(($O$6:$O$15=O24)*($Q$6:$Q$15)) -> 6
N25: 1500 | O25: Z-E1500U2SC | P25: =SUMPRODUCT(($O$6:$O$15=O25)*($Q$6:$Q$15)) -> 0
N26: 2000 | O26: Z-E2000U2SC | P26: =SUMPRODUCT(($O$6:$O$15=O26)*($Q$6:$Q$15)) -> 0
N27: 150 | O27: Z-E0150U2SH | P27: =SUMPRODUCT(($O$6:$O$15=O27)*($Q$6:$Q$15)) -> 0
N28: 250 | O28: Z-E0250U2SH | P28: =SUMPRODUCT(($O$6:$O$15=O28)*($Q$6:$Q$15)) -> 0
N29: 350 | O29: Z-E0350U2SH | P29: =SUMPRODUCT(($O$6:$O$15=O29)*($Q$6:$Q$15)) -> 0
N30: 500 | O30: Z-E0500U2SH | P30: =SUMPRODUCT(($O$6:$O$15=O30)*($Q$6:$Q$15)) -> 0
N31: 800 | O31: Z-E0800U2SH | P31: =SUMPRODUCT(($O$6:$O$15=O31)*($Q$6:$Q$15)) -> 0
N32: 합계 | P32: =SUM(P20:P31) -> 6
N33: 주거용
N34: 100 | O34: Z-E0100R(L)2AR | P34: =SUMPRODUCT(($O$6:$O$15=O34)*($Q$6:$Q$15)) -> 0
N35: 150 | O35: Z-E0150R(L)2AR | P35: =SUMPRODUCT(($O$6:$O$15=O35)*($Q$6:$Q$15)) -> 0
N36: 200 | O36: Z-E0200R(L)2AR | P36: =SUMPRODUCT(($O$6:$O$15=O36)*($Q$6:$Q$15)) -> 0
N37: 250 | O37: Z-E0250R(L)2AR | P37: =SUMPRODUCT(($O$6:$O$15=O37)*($Q$6:$Q$15)) -> 0
N38: 150 | O38: Z-H0151B2SR(L) | P38: =SUMPRODUCT(($O$6:$O$15=O38)*($Q$6:$Q$15)) -> 0
N39: 200 | O39: Z-H0201B2SR(L) | P39: =SUMPRODUCT(($O$6:$O$15=O39)*($Q$6:$Q$15)) -> 0
N40: 250 | O40: Z-H0251B2SR(L) | P40: =SUMPRODUCT(($O$6:$O$15=O40)*($Q$6:$Q$15)) -> 0
N41: 350 | O41: Z-H0301B2SR(L) | P41: =SUMPRODUCT(($O$6:$O$15=O41)*($Q$6:$Q$15)) -> 0
N42: 합계 | P42: =SUM(P34:P41) -> 0

Sheet Multi V Super,GHP
A1: ■ 냉난방 장비선정표
W2: ※ 본 도면의 부하/장비선정은 특정사례로 현장조건에 따라 달라 짐
A3: 층 별 | B3: 실 명 | C3: 면 적 | D3: 단위부하(kcal/h.㎡) | F3: 단위부하(w) | H3: 필요부하량(W) | J3: 장비 번호 | K3: 실내기 모델명 | L3: 냉방용량 | M3: 난방용량 | N3: 대수 | O3: 총냉방용량 | P3: 총난방용량 | Q3: 장비 번호 | R3: 실외기 모델명 | S3: 실외기냉방용량 | T3: 실외기난방용량 | U3: 대수 | V3: 조합비 | W3: 비 고
C4: ㎡ | D4: 냉방 | E4: 난방 | F4: 냉방 | G4: 난방 | H4: 냉방 | I4: 난방 | L4: (W) | M4: (W) | N4: (대) | O4: (W) | P4: (W) | S4: (W) | T4: (W) | U4: (대)
A5: 지하1층 | B5: 시청각실 | C5: 20 | D5: 140 | E5: =D5 -> 140 | F5: =D5/0.86 -> 162.7907 | G5: =E5/0.86 -> 162.7907 | H5: =C5*F5 -> 3255.814 | I5: =C5*G5 -> 3255.814 | J5: =INDEX($J$28:$J$50,MATCH(K5,$K$28:$K$50,0)) -> 40C | K5: RNW0401C2S | L5: =IF(ISERROR(VLOOKUP(K5,LG제품!$A$3:$C$271,2,0)),,VLOOKUP(K5,LG제품!$A$3:$C$271,2,0)) -> 4000 | M5: =IF(ISERROR(VLOOKUP(K5,LG제품!$A$3:$C$271,3,0)),,VLOOKUP(K5,LG제품!$A$3:$C$271,3,0)) -> 4500 | N5: 3 | O5: =L5*N5 -> 12000 | P5: =M5*N5 -> 13500 | Q5: =INDEX($Q$28:$Q$48,MATCH(R5,$R$28:$R$48,0)) -> 8 | R5: RPUW082X9E | S5: =IF(ISERROR(VLOOKUP(R5,LG제품!$E$3:$G$244,2,0)),,VLOOKUP(R5,LG제품!$E$3:$G$244,2,0)) -> 23300 | T5: =IF(ISERROR(VLOOKUP(R5,LG제품!$E$3:$G$244,3,0)),,VLOOKUP(R5,LG제품!$E$3:$G$244,3,0)) -> 25900 | U5: 1 | V5: =O7/S5 -> 0.77253219
B6: 준비실(위) | C6: 5.4 | D6: 150 | E6: =D6 -> 150 | F6: =D6/0.86 -> 174.4186 | G6: =E6/0.86 -> 174.4186 | H6: =C6*F6 -> 941.86047 | I6: =C6*G6 -> 941.86047 | J6: =INDEX($J$28:$J$50,MATCH(K6,$K$28:$K$50,0)) -> 20C | K6: RNW0201C2S | L6: =IF(ISERROR(VLOOKUP(K6,LG제품!$A$3:$C$271,2,0)),,VLOOKUP(K6,LG제품!$A$3:$C$271,2,0)) -> 2000 | M6: =IF(ISERROR(VLOOKUP(K6,LG제품!$A$3:$C$271,3,0)),,VLOOKUP(K6,LG제품!$A$3:$C$271,3,0)) -> 2200 | N6: 3 | O6: =L6*N6 -> 6000 | P6: =M6*N6 -> 6600
B7: 합계 | N7: =SUM(N5:N6) -> 6 | O7: =SUM(O5:O6) -> 18000 | P7: =SUM(P5:P6) -> 20100
A8: 지상1층 | B8: 미술실 | C8: 97.5 | D8: 180 | E8: =D8 -> 180 | F8: =D8/0.86 -> 209.30233 | G8: =E8/0.86 -> 209.30233 | H8: =C8*F8 -> 20406.977 | I8: =C8*G8 -> 20406.977 | J8: =INDEX($J$28:$J$50,MATCH(K8,$K$28:$K$50,0)) -> 110T | K8: RNW1101A2U | L8: =IF(ISERROR(VLOOKUP(K8,LG제품!$A$3:$C$271,2,0)),,VLOOKUP(K8,LG제품!$A$3:$C$271,2,0)) -> 11000 | M8: =IF(ISERROR(VLOOKUP(K8,LG제품!$A$3:$C$271,3,0)),,VLOOKUP(K8,LG제품!$A$3:$C$271,3,0)) -> 12400 | N8: 2 | O8: =L8*N8 -> 22000 | P8: =M8*N8 -> 24800 | Q8: =INDEX($Q$28:$Q$48,MATCH(R8,$R$28:$R$48,0)) -> 24 | R8: RPUW242X9E | S8: =IF(ISERROR(VLOOKUP(R8,LG제품!$E$3:$G$244,2,0)),,VLOOKUP(R8,LG제품!$E$3:$G$244,2,0)) -> 69600 | T8: =IF(ISERROR(VLOOKUP(R8,LG제품!$E$3:$G$244,3,0)),,VLOOKUP(R8,LG제품!$E$3:$G$244,3,0)) -> 78400 | U8: 1 | V8: =O13/S8 -> 1.1063218
B9: 준비실 | C9: 30.6 | D9: 150 | E9: =D9 -> 150 | F9: =D9/0.86 -> 174.4186 | G9: =E9/0.86 -> 174.4186 | H9: =C9*F9 -> 5337.2093 | I9: =C9*G9 -> 5337.2093 | J9: =INDEX($J$28:$J$50,MATCH(K9,$K$28:$K$50,0)) -> 110T | K9: RNW1101A2U | L9: =IF(ISERROR(VLOOKUP(K9,LG제품!$A$3:$C$271,2,0)),,VLOOKUP(K9,LG제품!$A$3:$C$271,2,0)) -> 11000 | M9: =IF(ISERROR(VLOOKUP(K9,LG제품!$A$3:$C$271,3,0)),,VLOOKUP(K9,LG제품!$A$3:$C$271,3,0)) -> 12400 | N9: 1 | O9: =L9*N9 -> 11000 | P9: =M9*N9 -> 12400
B10: 준비실 | C10: 27 | D10: 150 | E10: =D10 -> 150 | F10: =D10/0.86 -> 174.4186 | G10: =E10/0.86 -> 174.4186 | H10: =C10*F10 -> 4709.3023 | I10: =C10*G10 -> 4709.3023 | J10: =INDEX($J$28:$J$50,MATCH(K10,$K$28:$K$50,0)) -> 110T | K10: RNW1101A2U | L10: =IF(ISERROR(VLOOKUP(K10,LG제품!$A$3:$C$271,2,0)),,VLOOKUP(K10,LG제품!$A$3:$C$271,2,0)) -> 11000 | M10: =IF(ISERROR(VLOOKUP(K10,LG제품!$A$3:$C$271,3,0)),,VLOOKUP(K10,LG제품!$A$3:$C$271,3,0)) -> 12400 | N10: 1 | O10: =L10*N10 -> 11000 | P10: =M10*N10 -> 12400
B11: 기술실 | C11: 99 | D11: 180 | E11: =D11 -> 180 | F11: =D11/0.86 -> 209.30233 | G11: =E11/0.86 -> 209.30233 | H11: =C11*F11 -> 20720.93 | I11: =C11*G11 -> 20720.93 | J11: =INDEX($J$28:$J$50,MATCH(K11,$K$28:$K$50,0)) -> 110T | K11: RNW1101A2U | L11: =IF(ISERROR(VLOOKUP(K11,LG제품!$A$3:$C$271,2,0)),,VLOOKUP(K11,LG제품!$A$3:$C$271,2,0)) -> 11000 | M11: =IF(ISERROR(VLOOKUP(K11,LG제품!$A$3:$C$271,3,0)),,VLOOKUP(K11,LG제품!$A$3:$C$271,3,0)) -> 12400 | N11: 2 | O11: =L11*N11 -> 22000 | P11: =M11*N11 -> 24800
B12: 시설관리실 | C12: 22.2 | D12: 150 | E12: =D12 -> 150 | F12: =D12/0.86 -> 174.4186 | G12: =E12/0.86 -> 174.4186 | H12: =C12*F12 -> 3872.093 | I12: =C12*G12 -> 3872.093 | J12: =INDEX($J$28:$J$50,MATCH(K12,$K$28:$K$50,0)) -> 110T | K12: RNW1101A2U | L12: =IF(ISERROR(VLOOKUP(K12,LG제품!$A$3:$C$271,2,0)),,VLOOKUP(K12,LG제품!$A$3:$C$271,2,0)) -> 11000 | M12: =IF(ISERROR(VLOOKUP(K12,LG제품!$A$3:$C$271,3,0)),,VLOOKUP(K12,LG제품!$A$3:$C$271,3,0)) -> 12400 | N12: 1 | O12: =L12*N12 -> 11000 | P12: =M12*N12 -> 12400
B13: 합계 | N13: =SUM(N8:N12) -> 7 | O13: =SUM(O8:O12) -> 77000 | P13: =SUM(P8:P12) -> 86800
B14: 행정실 | C14: 64.8 | D14: 180 | E14: =D14 -> 180 | F14: =D14/0.86 -> 209.30233 | G14: =E14/0.86 -> 209.30233 | H14: =C14*F14 -> 13562.791 | I14: =C14*G14 -> 13562.791 | J14: =INDEX($J$28:$J$50,MATCH(K14,$K$28:$K$50,0)) -> 110T | K14: RNW1101A2U | L14: =IF(ISERROR(VLOOKUP(K14,LG제품!$A$3:$C$271,2,0)),,VLOOKUP(K14,LG제품!$A$3:$C$271,2,0)) -> 11000 | M14: =IF(ISERROR(VLOOKUP(K14,LG제품!$A$3:$C$271,3,0)),,VLOOKUP(K14,LG제품!$A$3:$C$271,3,0)) -> 12400 | N14: 1 | O14: =L14*N14 -> 11000 | P14: =M14*N14 -> 12400 | Q14: =INDEX($Q$28:$Q$48,MATCH(R14,$R$28:$R$48,0)) -> 24 | R14: RPUW242X9E | S14: =IF(ISERROR(VLOOKUP(R14,LG제품!$E$3:$G$244,2,0)),,VLOOKUP(R14,LG제품!$E$3:$G$244,2,0)) -> 69600 | T14: =IF(ISERROR(VLOOKUP(R14,LG제품!$E$3:$G$244,3,0)),,VLOOKUP(R14,LG제품!$E$3:$G$244,3,0)) -> 78400 | U14: 1 | V14: =O20/S14 -> 1.1063218
B15: 문서고 | C15: 16.9 | D15: 150 | E15: =D15 -> 150 | F15: =D15/0.86 -> 174.4186 | G15: =E15/0.86 -> 174.4186 | H15: =C15*F15 -> 2947.6744 | I15: =C15*G15 -> 2947.6744 | J15: =INDEX($J$28:$J$50,MATCH(K15,$K$28:$K$50,0)) -> 110T | K15: RNW1101A2U | L15: =IF(ISERROR(VLOOKUP(K15,LG제품!$A$3:$C$271,2,0)),,VLOOKUP(K15,LG제품!$A$3:$C$271,2,0)) -> 11000 | M15: =IF(ISERROR(VLOOKUP(K15,LG제품!$A$3:$C$271,3,0)),,VLOOKUP(K15,LG제품!$A$3:$C$271,3,0)) -> 12400 | N15: 1 | O15: =L15*N15 -> 11000 | P15: =M15*N15 -> 12400
B16: 교장실 | C16: 66.2 | D16: 160 | E16: =D16 -> 160 | F16: =D16/0.86 -> 186.04651 | G16: =E16/0.86 -> 186.04651 | H16: =C16*F16 -> 12316.279 | I16: =C16*G16 -> 12316.279 | J16: =INDEX($J$28:$J$50,MATCH(K16,$K$28:$K$50,0)) -> 110T | K16: RNW1101A2U | L16: =IF(ISERROR(VLOOKUP(K16,LG제품!$A$3:$C$271,2,0)),,VLOOKUP(K16,LG제품!$A$3:$C$271,2,0)) -> 11000 | M16: =IF(ISERROR(VLOOKUP(K16,LG제품!$A$3:$C$271,3,0)),,VLOOKUP(K16,LG제품!$A$3:$C$271,3,0)) -> 12400 | N16: 1 | O16: =L16*N16 -> 11000 | P16: =M16*N16 -> 12400
B17: 회의실 | C17: 32.2 | D17: 170 | E17: =D17 -> 170 | F17: =D17/0.86 -> 197.67442 | G17: =E17/0.86 -> 197.67442 | H17: =C17*F17 -> 6365.1163 | I17: =C17*G17 -> 6365.1163 | J17: =INDEX($J$28:$J$50,MATCH(K17,$K$28:$K$50,0)) -> 110T | K17: RNW1101A2U | L17: =IF(ISERROR(VLOOKUP(K17,LG제품!$A$3:$C$271,2,0)),,VLOOKUP(K17,LG제품!$A$3:$C$271,2,0)) -> 11000 | M17: =IF(ISERROR(VLOOKUP(K17,LG제품!$A$3:$C$271,3,0)),,VLOOKUP(K17,LG제품!$A$3:$C$271,3,0)) -> 12400 | N17: 1 | O17: =L17*N17 -> 11000 | P17: =M17*N17 -> 12400
B18: 임산교사휴게실 | C18: 32.2 | D18: 170 | E18: =D18 -> 170 | F18: =D18/0.86 -> 197.67442 | G18: =E18/0.86 -> 197.67442 | H18: =C18*F18 -> 6365.1163 | I18: =C18*G18 -> 6365.1163 | J18: =INDEX($J$28:$J$50,MATCH(K18,$K$28:$K$50,0)) -> 110T | K18: RNW1101A2U | L18: =IF(ISERROR(VLOOKUP(K18,LG제품!$A$3:$C$271,2,0)),,VLOOKUP(K18,LG제품!$A$3:$C$271,2,0)) -> 11000 | M18: =IF(ISERROR(VLOOKUP(K18,LG제품!$A$3:$C$271,3,0)),,VLOOKUP(K18,LG제품!$A$3:$C$271,3,0)) -> 12400 | N18: 1 | O18: =L18*N18 -> 11000 | P18: =M18*N18 -> 12400
B19: 보건실 | C19: 65.2 | D19: 170 | E19: =D19 -> 170 | F19: =D19/0.86 -> 197.67442 | G19: =E19/0.86 -> 197.67442 | H19: =C19*F19 -> 12888.372 | I19: =C19*G19 -> 12888.372 | J19: =INDEX($J$28:$J$50,MATCH(K19,$K$28:$K$50,0)) -> 110T | K19: RNW1101A2U | L19: =IF(ISERROR(VLOOKUP(K19,LG제품!$A$3:$C$271,2,0)),,VLOOKUP(K19,LG제품!$A$3:$C$271,2,0)) -> 11000 | M19: =IF(ISERROR(VLOOKUP(K19,LG제품!$A$3:$C$271,3,0)),,VLOOKUP(K19,LG제품!$A$3:$C$271,3,0)) -> 12400 | N19: 2 | O19: =L19*N19 -> 22000 | P19: =M19*N19 -> 24800
B20: 합계 | N20: =SUM(N14:N19) -> 7 | O20: =SUM(O14:O19) -> 77000 | P20: =SUM(P14:P19) -> 86800
N21: =SUM(N20,N13,N7) -> 20 | U21: =SUM(U5:U20) -> 3
A22: ※ NOTE
A23: 1. 최종보정값은 배관길이,온도차,제상운전에 관한 보정계수 적용값이며, 보정계수는 장비 및 현장조건에 따라 달라짐.
A24: 2. 최종보정값은 실별 필요부하량을 만족해야함.
A25: 3. 실내/외기 조합비는 100%이내여야 함.
J27: 실내기 | Q27: 실외기 | U27: HP | V27: HP계
J28: 20C | K28: RNW0201C2S | L28: =SUMPRODUCT(($K$5:$K$20=K28)*($N$5:$N$20)) -> 3 | Q28: 8 | R28: RPUW082X9E | S28: =SUMPRODUCT(($R$5:$R$20=R28)*($U$5:$U$20)) -> 1 | U28: =MID(R28,5,2) -> 08 | V28: =U28*S28 -> 8
J29: 23C | K29: RNW0231C2S | L29: =SUMPRODUCT(($K$5:$K$20=K29)*($N$5:$N$20)) -> 0 | Q29: 10 | R29: RPUW102X9E | S29: =SUMPRODUCT(($R$5:$R$20=R29)*($U$5:$U$20)) -> 0 | U29: =MID(R29,5,2) -> 10 | V29: =U29*S29 -> 0
J30: 32C | K30: RNW0321C2S | L30: =SUMPRODUCT(($K$5:$K$20=K30)*($N$5:$N$20)) -> 0 | Q30: 12 | R30: RPUW122X9E | S30: =SUMPRODUCT(($R$5:$R$20=R30)*($U$5:$U$20)) -> 0 | U30: =MID(R30,5,2) -> 12 | V30: =U30*S30 -> 0
J31: 40C | K31: RNW0401C2S | L31: =SUMPRODUCT(($K$5:$K$20=K31)*($N$5:$N$20)) -> 3 | Q31: 14 | R31: RPUW142X9E | S31: =SUMPRODUCT(($R$5:$R$20=R31)*($U$5:$U$20)) -> 0 | U31: =MID(R31,5,2) -> 14 | V31: =U31*S31 -> 0
J32: 52C | K32: RNW0521C2S | L32: =SUMPRODUCT(($K$5:$K$20=K32)*($N$5:$N$20)) -> 0 | Q32: 16 | R32: RPUW162X9E | S32: =SUMPRODUCT(($R$5:$R$20=R32)*($U$5:$U$20)) -> 0 | U32: =MID(R32,5,2) -> 16 | V32: =U32*S32 -> 0
J33: 60C | K33: RNW0601C2S | L33: =SUMPRODUCT(($K$5:$K$20=K33)*($N$5:$N$20)) -> 0 | Q33: 18 | R33: RPUW182X9E | S33: =SUMPRODUCT(($R$5:$R$20=R33)*($U$5:$U$20)) -> 0 | U33: =MID(R33,5,2) -> 18 | V33: =U33*S33 -> 0
J34: 72C | K34: RNW0721C2S | L34: =SUMPRODUCT(($K$5:$K$20=K34)*($N$5:$N$20)) -> 0 | Q34: 20 | R34: RPUW202X9E | S34: =SUMPRODUCT(($R$5:$R$20=R34)*($U$5:$U$20)) -> 0 | U34: =MID(R34,5,2) -> 20 | V34: =U34*S34 -> 0
J35: 52G | K35: RNW0521G2S | L35: =SUMPRODUCT(($K$5:$K$20=K35)*($N$5:$N$20)) -> 0 | Q35: 22 | R35: RPUW222X9E | S35: =SUMPRODUCT(($R$5:$R$20=R35)*($U$5:$U$20)) -> 0 | U35: =MID(R35,5,2) -> 22 | V35: =U35*S35 -> 0
J36: 60G | K36: RNW0601G2S | L36: =SUMPRODUCT(($K$5:$K$20=K36)*($N$5:$N$20)) -> 0 | Q36: 24 | R36: RPUW242X9E | S36: =SUMPRODUCT(($R$5:$R$20=R36)*($U$5:$U$20)) -> 2 | U36: =MID(R36,5,2) -> 24 | V36: =U36*S36 -> 48
J37: 72G | K37: RNW0721G2S | L37: =SUMPRODUCT(($K$5:$K$20=K37)*($N$5:$N$20)) -> 0 | Q37: 26 | R37: RP-W262X9E | S37: =SUMPRODUCT(($R$5:$R$20=R37)*($U$5:$U$20)) -> 0 | U37: =MID(R37,5,2) -> 26 | V37: =U37*S37 -> 0
J38: 23M | K38: RNW0230M2S | L38: =SUMPRODUCT(($K$5:$K$20=K38)*($N$5:$N$20)) -> 0 | Q38: 28 | R38: RP-W282X9E | S38: =SUMPRODUCT(($R$5:$R$20=R38)*($U$5:$U$20)) -> 0 | U38: =MID(R38,5,2) -> 28 | V38: =U38*S38 -> 0
J39: 32M | K39: RNW0320M2S | L39: =SUMPRODUCT(($K$5:$K$20=K39)*($N$5:$N$20)) -> 0 | Q39: 30 | R39: RP-W302X9E | S39: =SUMPRODUCT(($R$5:$R$20=R39)*($U$5:$U$20)) -> 0 | U39: =MID(R39,5,2) -> 30 | V39: =U39*S39 -> 0
... J48: 110T | K48: RNW1101A2U | L48: =SUMPRODUCT(($K$5:$K$20=K48)*($N$5:$N$20)) -> 14 | Q48: 48 | R48: RP-W482X9E | S48: =SUMPRODUCT(($R$5:$R$20=R48)*($U$5:$U$20)) -> 0 | U48: =MID(R48,5,2) -> 48 | V48: =U48*S48 -> 0
J49: 130T | K49: RNW1301A2U | L49: =SUMPRODUCT(($K$5:$K$20=K49)*($N$5:$N$20)) -> 0 | Q49: 합계 | S49: =SUM(S28:S48) -> 3 | U49: 계 | V49: =SUM(V27:V48) -> 56
...

Sheet DOAS
A1: ■ DOAS 냉난방 장비선정표
W2: ※ 본 도면의 부하/장비선정은 특정사례로 현장조건에 따라 달라 짐
A3: 층 별 | B3: 실 명 | C3: 면 적 | D3: 단위부하(kcal/h.㎡) | F3: 단위부하(w) | H3: 필요부하량(W) | J3: 장비 번호 | K3: 실내기 모델명 | L3: 냉방용량 | M3: 난방용량 | N3: 대수 | O3: 총냉방용량 | P3: 총난방용량 | Q3: 장비 번호 | R3: 실외기 모델명 | S3: 실외기냉방용량 | T3: 실외기난방용량 | U3: 대수 | V3: 조합비 | W3: 비 고
C4: ㎡ | D4: 냉방 | E4: 난방 | F4: 냉방 | G4: 난방 | H4: 냉방 | I4: 난방 | L4: (W) | M4: (W) | N4: (대) | O4: (W) | P4: (W) | S4: (W) | T4: (W) | U4: (대)
A5: 지상1층 | B5: 창고 | C5: 97.5 | D5: 230 | E5: =D5 -> 230 | F5: =D5/0.86 -> 267.44186 | G5: =E5/0.86 -> 267.44186 | H5: =C5*F5 -> 26075.581 | I5: =C5*G5 -> 26075.581 | J5: =INDEX($J$19:$J$24,MATCH(K5,$K$19:$K$24,0)) -> 123D | K5: RNW1230X2SS (실) | L5: =IF(ISERROR(VLOOKUP(K5,LG제품!$A$3:$C$271,2,0)),,VLOOKUP(K5,LG제품!$A$3:$C$271,2,0)) -> 7500 | M5: =IF(ISERROR(VLOOKUP(K5,LG제품!$A$3:$C$271,3,0)),,VLOOKUP(K5,LG제품!$A$3:$C$271,3,0)) -> 7000 | N5: 1 | O5: =L5*N5 -> 7500 | P5: =M5*N5 -> 7000 | Q5: =INDEX($Q$19:$Q$47,MATCH(R5,$R$19:$R$47,0)) -> 8 | R5: RPUB081X9E | S5: =IF(ISERROR(VLOOKUP(R5,LG제품!$I$82:$K$109,2,0)),,VLOOKUP(R5,LG제품!$I$82:$K$109,2,0)) -> 23300 | T5: =IF(ISERROR(VLOOKUP(R5,LG제품!$I$82:$K$109,3,0)),,VLOOKUP(R5,LG제품!$I$82:$K$109,3,0)) -> 25900 | U5: 1 | V5: =O6/S5 -> 0.32188841
B6: 합계 | N6: =SUM(N5) -> 1 | O6: =SUM(O5) -> 7500 | P6: =SUM(P5) -> 7000
B7: 창고 | C7: 30.6 | D7: 230 | E7: =D7 -> 230 | F7: =D7/0.86 -> 267.44186 | G7: =E7/0.86 -> 267.44186 | H7: =C7*F7 -> 8183.7209 | I7: =C7*G7 -> 8183.7209 | J7: =INDEX($J$19:$J$24,MATCH(K7,$K$19:$K$24,0)) -> 123D | K7: RNW1230X2SS (외) | L7: =IF(ISERROR(VLOOKUP(K7,LG제품!$A$3:$C$271,2,0)),,VLOOKUP(K7,LG제품!$A$3:$C$271,2,0)) -> 12300 | M7: =IF(ISERROR(VLOOKUP(K7,LG제품!$A$3:$C$271,3,0)),,VLOOKUP(K7,LG제품!$A$3:$C$271,3,0)) -> 8800 | N7: 2 | O7: =L7*N7 -> 24600 | P7: =M7*N7 -> 17600 | Q7: =INDEX($Q$19:$Q$47,MATCH(R7,$R$19:$R$47,0)) -> S5 | R7: RPUM050S2S | S7: =IF(ISERROR(VLOOKUP(R7,LG제품!$I$82:$K$109,2,0)),,VLOOKUP(R7,LG제품!$I$82:$K$109,2,0)) -> 14500 | T7: =IF(ISERROR(VLOOKUP(R7,LG제품!$I$82:$K$109,3,0)),,VLOOKUP(R7,LG제품!$I$82:$K$109,3,0)) -> 16300 | U7: 1 | V7: =O8/S7 -> 1.6965517
B8: 합계 | N8: =SUM(N7) -> 2 | O8: =SUM(O7) -> 24600 | P8: =SUM(P7) -> 17600
B9: 창고 | C9: 150 | D9: 230 | E9: =D9 -> 230 | F9: =D9/0.86 -> 267.44186 | G9: =E9/0.86 -> 267.44186 | H9: =C9*F9 -> 40116.279 | I9: =C9*G9 -> 40116.279 | J9: =INDEX($J$19:$J$24,MATCH(K9,$K$19:$K$24,0)) -> 203D | K9: ARND203DCR6 (실) | L9: =IF(ISERROR(VLOOKUP(K9,LG제품!$A$3:$C$271,2,0)),,VLOOKUP(K9,LG제품!$A$3:$C$271,2,0)) -> 30000 | M9: =IF(ISERROR(VLOOKUP(K9,LG제품!$A$3:$C$271,3,0)),,VLOOKUP(K9,LG제품!$A$3:$C$271,3,0)) -> 28000 | N9: 1 | O9: =L9*N9 -> 30000 | P9: =M9*N9 -> 28000 | Q9: =INDEX($Q$19:$Q$47,MATCH(R9,$R$19:$R$47,0)) -> 46 | R9: RP-B461X9E | S9: =IF(ISERROR(VLOOKUP(R9,LG제품!$I$82:$K$109,2,0)),,VLOOKUP(R9,LG제품!$I$82:$K$109,2,0)) -> 131500 | T9: =IF(ISERROR(VLOOKUP(R9,LG제품!$I$82:$K$109,3,0)),,VLOOKUP(R9,LG제품!$I$82:$K$109,3,0)) -> 146000 | U9: 1 | V9: =O11/S9 -> 0.86539924
B10: 창고 | C10: 300 | D10: 230 | E10: =D10 -> 230 | F10: =D10/0.86 -> 267.44186 | G10: =E10/0.86 -> 267.44186 | H10: =C10*F10 -> 80232.558 | I10: =C10*G10 -> 80232.558 | J10: =INDEX($J$19:$J$24,MATCH(K10,$K$19:$K$24,0)) -> 203D | K10: ARND203DCR6 (외) | L10: =IF(ISERROR(VLOOKUP(K10,LG제품!$A$3:$C$271,2,0)),,VLOOKUP(K10,LG제품!$A$3:$C$271,2,0)) -> 41900 | M10: =IF(ISERROR(VLOOKUP(K10,LG제품!$A$3:$C$271,3,0)),,VLOOKUP(K10,LG제품!$A$3:$C$271,3,0)) -> 29300 | N10: 2 | O10: =L10*N10 -> 83800 | P10: =M10*N10 -> 58600
B11: 합계 | N11: =SUM(N9:N10) -> 3 | O11: =SUM(O9:O10) -> 113800 | P11: =SUM(P9:P10) -> 86600
N12: =SUM(N11,N8) -> 5 | U12: =SUM(U5:U11) -> 3
A13: ※ NOTE
A14: 1. 최종보정값은 배관길이,온도차,제상운전에 관한 보정계수 적용값이며, 보정계수는 장비 및 현장조건에 따라 달라짐.
A15: 2. 최종보정값은 실별 필요부하량을 만족해야함.
A16: 3. 실내/외기 조합비는 100%이내여야 함.
J18: DOAS | Q18: 멀티V I 냉난방 동시형 | U18: HP | V18: HP계
J19: 123D | K19: RNW1230X2SS (실) | L19: =SUMPRODUCT(($K$5:$K$11=K19)*($N$5:$N$11)) -> 1 | Q19: 14 | R19: RPUB142XDE | S19: =SUMPRODUCT(($R$5:$R$11=R19)*($U$5:$U$11)) -> 0 | U19: =MID(R19,5,2) -> 14 | V19: =U19*S19 -> 0
J20: 153D | K20: ARND153DCR6 (실) | L20: =SUMPRODUCT(($K$5:$K$11=K20)*($N$5:$N$11)) -> 0 | Q20: 28 | R20: RP-B282XDE | S20: =SUMPRODUCT(($R$5:$R$11=R20)*($U$5:$U$11)) -> 0 | U20: =MID(R20,5,2) -> 28 | V20: =U20*S20 -> 0
J21: 203D | K21: ARND203DCR6 (실) | L21: =SUMPRODUCT(($K$5:$K$11=K21)*($N$5:$N$11)) -> 1 | Q21: 42 | R21: RP-B422XDE | S21: =SUMPRODUCT(($R$5:$R$11=R21)*($U$5:$U$11)) -> 0 | U21: =MID(R21,5,2) -> 42 | V21: =U21*S21 -> 0
J22: 123D | K22: RNW1230X2SS (외) | L22: =SUMPRODUCT(($K$5:$K$11=K22)*($N$5:$N$11)) -> 2 | Q22: 합계 | S22: =SUM(S19:S21) -> 0
J23: 153D | K23: ARND153DCR6 (외) | L23: =SUMPRODUCT(($K$5:$K$11=K23)*($N$5:$N$11)) -> 0 | Q23: 멀티V S 냉난방 동시형
J24: 203D | K24: ARND203DCR6 (외) | L24: =SUMPRODUCT(($K$5:$K$11=K24)*($N$5:$N$11)) -> 2 | Q24: S5 | R24: RPUM050S2S | S24: =SUMPRODUCT(($R$5:$R$11=R24)*($U$5:$U$11)) -> 1 | U24: =MID(R24,5,2) -> 05 | V24: =U24*S24 -> 5
J25: 합계 | L25: =SUM(L19:L24) -> 6 | Q25: 합계 | S25: =SUM(S24) -> 1
Q26: 동시형 실외기
Q27: 8 | R27: RPUB081X9E | S27: =SUMPRODUCT(($R$5:$R$11=R27)*($U$5:$U$11)) -> 1 | U27: =MID(R27,5,2) -> 08 | V27: =U27*S27 -> 8
Q28: 10 | R28: RPUB101X9E | S28: =SUMPRODUCT(($R$5:$R$11=R28)*($U$5:$U$11)) -> 0 | U28: =MID(R28,5,2) -> 10 | V28: =U28*S28 -> 0
Q29: 12 | R29: RPUB121X9E | S29: =SUMPRODUCT(($R$5:$R$11=R29)*($U$5:$U$11)) -> 0 | U29: =MID(R29,5,2) -> 12 | V29: =U29*S29 -> 0
Q30: 14 | R30: RPUB141X9E | S30: =SUMPRODUCT(($R$5:$R$11=R30)*($U$5:$U$11)) -> 0 | U30: =MID(R30,5,2) -> 14 | V30: =U30*S30 -> 0
Q31: 16 | R31: RPUB161X9E | S31: =SUMPRODUCT(($R$5:$R$11=R31)*($U$5:$U$11)) -> 0 | U31: =MID(R31,5,2) -> 16 | V31: =U31*S31 -> 0
Q32: 18 | R32: RPUB181X9E | S32: =SUMPRODUCT(($R$5:$R$11=R32)*($U$5:$U$11)) -> 0 | U32: =MID(R32,5,2) -> 18 | V32: =U32*S32 -> 0
Q33: 20 | R33: RPUB201X9E | S33: =SUMPRODUCT(($R$5:$R$11=R33)*($U$5:$U$11)) -> 0 | U33: =MID(R33,5,2) -> 20 | V33: =U33*S33 -> 0
Q34: 22 | R34: RPUB221X9E | S34: =SUMPRODUCT(($R$5:$R$11=R34)*($U$5:$U$11)) -> 0 | U34: =MID(R34,5,2) -> 22 | V34: =U34*S34 -> 0
Q35: 24 | R35: RPUB241X9E | S35: =SUMPRODUCT(($R$5:$R$11=R35)*($U$5:$U$11)) -> 0 | U35: =MID(R35,5,2) -> 24 | V35: =U35*S35 -> 0
Q36: 26 | R36: RP-B261X9E | S36: =SUMPRODUCT(($R$5:$R$11=R36)*($U$5:$U$11)) -> 0 | U36: =MID(R36,5,2) -> 26 | V36: =U36*S36 -> 0
Q37: 28 | R37: RP-B281X9E | S37: =SUMPRODUCT(($R$5:$R$11=R37)*($U$5:$U$11)) -> 0 | U37: =MID(R37,5,2) -> 28 | V37: =U37*S37 -> 0
Q38: 30 | R38: RP-B301X9E | S38: =SUMPRODUCT(($R$5:$R$11=R38)*($U$5:$U$11)) -> 0 | U38: =MID(R38,5,2) -> 30 | V38: =U38*S38 -> 0
... Q45: 44 | R45: RP-B441X9E | S45: =SUMPRODUCT(($R$5:$R$11=R45)*($U$5:$U$11)) -> 0 | U45: =MID(R45,5,2) -> 44 | V45: =U45*S45 -> 0
Q46: 46 | R46: RP-B461X9E | S46: =SUMPRODUCT(($R$5:$R$11=R46)*($U$5:$U$11)) -> 1 | U46: =MID(R39,5,2) -> 32 | V46: =U46*S39 -> 0
Q47: 48 | R47: RP-B481X9E | S47: =SUMPRODUCT(($R$5:$R$11=R47)*($U$5:$U$11)) -> 0 | U47: =MID(R40,5,2) -> 34 | V47: =U47*S40 -> 0
...

Sheet 하이브리드
A1: ■ 냉난방 장비선정표
W2: ※ 본 도면의 부하/장비선정은 특정사례로 현장조건에 따라 달라 짐
A3: 층 별 | B3: 실 명 | C3: 면 적 | D3: 단위부하(kcal/h.㎡) | F3: 단위부하(w) | H3: 필요부하량(W) | J3: 장비 번호 | K3: 실내기 모델명 | L3: 냉방용량 | M3: 난방용량 | N3: 대수 | O3: 총냉방용량 | P3: 총난방용량 | Q3: 장비 번호 | R3: 실외기 모델명 | S3: 실외기냉방용량 | T3: 실외기난방용량 | U3: 대수 | V3: 조합비 | W3: 비 고
C4: ㎡ | D4: 냉방 | E4: 난방 | F4: 냉방 | G4: 난방 | H4: 냉방 | I4: 난방 | L4: (W) | M4: (W) | N4: (대) | O4: (W) | P4: (W) | S4: (W) | T4: (W) | U4: (대)
A5: 지하1층 | B5: 시청각실 | C5: 20 | D5: 140 | E5: =D5 -> 140 | F5: =D5/0.86 -> 162.7907 | G5: =E5/0.86 -> 162.7907 | H5: =C5*F5 -> 3255.814 | I5: =C5*G5 -> 3255.814 | J5: =INDEX($J$28:$J$50,MATCH(K5,$K$28:$K$50,0)) -> 110T | K5: RNW1101A2U | L5: =IF(ISERROR(VLOOKUP(K5,LG제품!$A$3:$C$271,2,0)),,VLOOKUP(K5,LG제품!$A$3:$C$271,2,0)) -> 11000 | M5: =IF(ISERROR(VLOOKUP(K5,LG제품!$A$3:$C$271,3,0)),,VLOOKUP(K5,LG제품!$A$3:$C$271,3,0)) -> 12400 | N5: 3 | O5: =L5*N5 -> 33000 | P5: =M5*N5 -> 37200 | Q5: =INDEX($Q$28:$Q$43,MATCH(R5,$R$28:$R$43,0)) -> 24 | R5: GPHW241C1E1 | S5: =IF(ISERROR(VLOOKUP(R5,LG제품!$E$3:$G$244,2,0)),,VLOOKUP(R5,LG제품!$E$3:$G$244,2,0)) -> 68300 | T5: =IF(ISERROR(VLOOKUP(R5,LG제품!$E$3:$G$244,3,0)),,VLOOKUP(R5,LG제품!$E$3:$G$244,3,0)) -> 75900 | U5: 1 | V5: =O7/S5 -> 0.96632504
B6: 준비실(위) | C6: 5.4 | D6: 150 | E6: =D6 -> 150 | F6: =D6/0.86 -> 174.4186 | G6: =E6/0.86 -> 174.4186 | H6: =C6*F6 -> 941.86047 | I6: =C6*G6 -> 941.86047 | J6: =INDEX($J$28:$J$50,MATCH(K6,$K$28:$K$50,0)) -> 110T | K6: RNW1101A2U | L6: =IF(ISERROR(VLOOKUP(K6,LG제품!$A$3:$C$271,2,0)),,VLOOKUP(K6,LG제품!$A$3:$C$271,2,0)) -> 11000 | M6: =IF(ISERROR(VLOOKUP(K6,LG제품!$A$3:$C$271,3,0)),,VLOOKUP(K6,LG제품!$A$3:$C$271,3,0)) -> 12400 | N6: 3 | O6: =L6*N6 -> 33000 | P6: =M6*N6 -> 37200
B7: 합계 | N7: =SUM(N5:N6) -> 6 | O7: =SUM(O5:O6) -> 66000 | P7: =SUM(P5:P6) -> 74400
A8: 지상1층 | B8: 미술실 | C8: 97.5 | D8: 180 | E8: =D8 -> 180 | F8: =D8/0.86 -> 209.30233 | G8: =E8/0.86 -> 209.30233 | H8: =C8*F8 -> 20406.977 | I8: =C8*G8 -> 20406.977 | J8: =INDEX($J$28:$J$50,MATCH(K8,$K$28:$K$50,0)) -> 110T | K8: RNW1101A2U | L8: =IF(ISERROR(VLOOKUP(K8,LG제품!$A$3:$C$271,2,0)),,VLOOKUP(K8,LG제품!$A$3:$C$271,2,0)) -> 11000 | M8: =IF(ISERROR(VLOOKUP(K8,LG제품!$A$3:$C$271,3,0)),,VLOOKUP(K8,LG제품!$A$3:$C$271,3,0)) -> 12400 | N8: 2 | O8: =L8*N8 -> 22000 | P8: =M8*N8 -> 24800 | Q8: =INDEX($Q$28:$Q$43,MATCH(R8,$R$28:$R$43,0)) -> 46 | R8: GPHW461C4E6 | S8: =IF(ISERROR(VLOOKUP(R8,LG제품!$E$3:$G$244,2,0)),,VLOOKUP(R8,LG제품!$E$3:$G$244,2,0)) -> 134200 | T8: =IF(ISERROR(VLOOKUP(R8,LG제품!$E$3:$G$244,3,0)),,VLOOKUP(R8,LG제품!$E$3:$G$244,3,0)) -> 148700 | U8: 1 | V8: =O13/S8 -> 0.57377049
B9: 준비실 | C9: 30.6 | D9: 150 | E9: =D9 -> 150 | F9: =D9/0.86 -> 174.4186 | G9: =E9/0.86 -> 174.4186 | H9: =C9*F9 -> 5337.2093 | I9: =C9*G9 -> 5337.2093 | J9: =INDEX($J$28:$J$50,MATCH(K9,$K$28:$K$50,0)) -> 110T | K9: RNW1101A2U | L9: =IF(ISERROR(VLOOKUP(K9,LG제품!$A$3:$C$271,2,0)),,VLOOKUP(K9,LG제품!$A$3:$C$271,2,0)) -> 11000 | M9: =IF(ISERROR(VLOOKUP(K9,LG제품!$A$3:$C$271,3,0)),,VLOOKUP(K9,LG제품!$A$3:$C$271,3,0)) -> 12400 | N9: 1 | O9: =L9*N9 -> 11000 | P9: =M9*N9 -> 12400
B10: 준비실 | C10: 27 | D10: 150 | E10: =D10 -> 150 | F10: =D10/0.86 -> 174.4186 | G10: =E10/0.86 -> 174.4186 | H10: =C10*F10 -> 4709.3023 | I10: =C10*G10 -> 4709.3023 | J10: =INDEX($J$28:$J$50,MATCH(K10,$K$28:$K$50,0)) -> 110T | K10: RNW1101A2U | L10: =IF(ISERROR(VLOOKUP(K10,LG제품!$A$3:$C$271,2,0)),,VLOOKUP(K10,LG제품!$A$3:$C$271,2,0)) -> 11000 | M10: =IF(ISERROR(VLOOKUP(K10,LG제품!$A$3:$C$271,3,0)),,VLOOKUP(K10,LG제품!$A$3:$C$271,3,0)) -> 12400 | N10: 1 | O10: =L10*N10 -> 11000 | P10: =M10*N10 -> 12400
B11: 기술실 | C11: 99 | D11: 180 | E11: =D11 -> 180 | F11: =D11/0.86 -> 209.30233 | G11: =E11/0.86 -> 209.30233 | H11: =C11*F11 -> 20720.93 | I11: =C11*G11 -> 20720.93 | J11: =INDEX($J$28:$J$50,MATCH(K11,$K$28:$K$50,0)) -> 110T | K11: RNW1101A2U | L11: =IF(ISERROR(VLOOKUP(K11,LG제품!$A$3:$C$271,2,0)),,VLOOKUP(K11,LG제품!$A$3:$C$271,2,0)) -> 11000 | M11: =IF(ISERROR(VLOOKUP(K11,LG제품!$A$3:$C$271,3,0)),,VLOOKUP(K11,LG제품!$A$3:$C$271,3,0)) -> 12400 | N11: 2 | O11: =L11*N11 -> 22000 | P11: =M11*N11 -> 24800
B12: 시설관리실 | C12: 22.2 | D12: 150 | E12: =D12 -> 150 | F12: =D12/0.86 -> 174.4186 | G12: =E12/0.86 -> 174.4186 | H12: =C12*F12 -> 3872.093 | I12: =C12*G12 -> 3872.093 | J12: =INDEX($J$28:$J$50,MATCH(K12,$K$28:$K$50,0)) -> 110T | K12: RNW1101A2U | L12: =IF(ISERROR(VLOOKUP(K12,LG제품!$A$3:$C$271,2,0)),,VLOOKUP(K12,LG제품!$A$3:$C$271,2,0)) -> 11000 | M12: =IF(ISERROR(VLOOKUP(K12,LG제품!$A$3:$C$271,3,0)),,VLOOKUP(K12,LG제품!$A$3:$C$271,3,0)) -> 12400 | N12: 1 | O12: =L12*N12 -> 11000 | P12: =M12*N12 -> 12400
B13: 합계 | N13: =SUM(N8:N12) -> 7 | O13: =SUM(O8:O12) -> 77000 | P13: =SUM(P8:P12) -> 86800
B14: 행정실 | C14: 64.8 | D14: 180 | E14: =D14 -> 180 | F14: =D14/0.86 -> 209.30233 | G14: =E14/0.86 -> 209.30233 | H14: =C14*F14 -> 13562.791 | I14: =C14*G14 -> 13562.791 | J14: =INDEX($J$28:$J$50,MATCH(K14,$K$28:$K$50,0)) -> 110T | K14: RNW1101A2U | L14: =IF(ISERROR(VLOOKUP(K14,LG제품!$A$3:$C$271,2,0)),,VLOOKUP(K14,LG제품!$A$3:$C$271,2,0)) -> 11000 | M14: =IF(ISERROR(VLOOKUP(K14,LG제품!$A$3:$C$271,3,0)),,VLOOKUP(K14,LG제품!$A$3:$C$271,3,0)) -> 12400 | N14: 1 | O14: =L14*N14 -> 11000 | P14: =M14*N14 -> 12400 | Q14: =INDEX($Q$28:$Q$43,MATCH(R14,$R$28:$R$43,0)) -> 48 | R14: GPHW481C6E5 | S14: =IF(ISERROR(VLOOKUP(R14,LG제품!$E$3:$G$244,2,0)),,VLOOKUP(R14,LG제품!$E$3:$G$244,2,0)) -> 136400 | T14: =IF(ISERROR(VLOOKUP(R14,LG제품!$E$3:$G$244,3,0)),,VLOOKUP(R14,LG제품!$E$3:$G$244,3,0)) -> 152200 | U14: 1 | V14: =O20/S14 -> 0.48387097
B15: 문서고 | C15: 16.9 | D15: 150 | E15: =D15 -> 150 | F15: =D15/0.86 -> 174.4186 | G15: =E15/0.86 -> 174.4186 | H15: =C15*F15 -> 2947.6744 | I15: =C15*G15 -> 2947.6744 | J15: =INDEX($J$28:$J$50,MATCH(K15,$K$28:$K$50,0)) -> 110T | K15: RNW1101A2U | L15: =IF(ISERROR(VLOOKUP(K15,LG제품!$A$3:$C$271,2,0)),,VLOOKUP(K15,LG제품!$A$3:$C$271,2,0)) -> 11000 | M15: =IF(ISERROR(VLOOKUP(K15,LG제품!$A$3:$C$271,3,0)),,VLOOKUP(K15,LG제품!$A$3:$C$271,3,0)) -> 12400 | N15: 1 | O15: =L15*N15 -> 11000 | P15: =M15*N15 -> 12400
B16: 교장실 | C16: 66.2 | D16: 160 | E16: =D16 -> 160 | F16: =D16/0.86 -> 186.04651 | G16: =E16/0.86 -> 186.04651 | H16: =C16*F16 -> 12316.279 | I16: =C16*G16 -> 12316.279 | J16: =INDEX($J$28:$J$50,MATCH(K16,$K$28:$K$50,0)) -> 110T | K16: RNW1101A2U | L16: =IF(ISERROR(VLOOKUP(K16,LG제품!$A$3:$C$271,2,0)),,VLOOKUP(K16,LG제품!$A$3:$C$271,2,0)) -> 11000 | M16: =IF(ISERROR(VLOOKUP(K16,LG제품!$A$3:$C$271,3,0)),,VLOOKUP(K16,LG제품!$A$3:$C$271,3,0)) -> 12400 | N16: 1 | O16: =L16*N16 -> 11000 | P16: =M16*N16 -> 12400
B17: 회의실 | C17: 32.2 | D17: 170 | E17: =D17 -> 170 | F17: =D17/0.86 -> 197.67442 | G17: =E17/0.86 -> 197.67442 | H17: =C17*F17 -> 6365.1163 | I17: =C17*G17 -> 6365.1163 | J17: =INDEX($J$28:$J$50,MATCH(K17,$K$28:$K$50,0)) -> 110T | K17: RNW1101A2U | L17: =IF(ISERROR(VLOOKUP(K17,LG제품!$A$3:$C$271,2,0)),,VLOOKUP(K17,LG제품!$A$3:$C$271,2,0)) -> 11000 | M17: =IF(ISERROR(VLOOKUP(K17,LG제품!$A$3:$C$271,3,0)),,VLOOKUP(K17,LG제품!$A$3:$C$271,3,0)) -> 12400 | N17: 1 | O17: =L17*N17 -> 11000 | P17: =M17*N17 -> 12400
B18: 임산교사휴게실 | C18: 32.2 | D18: 170 | E18: =D18 -> 170 | F18: =D18/0.86 -> 197.67442 | G18: =E18/0.86 -> 197.67442 | H18: =C18*F18 -> 6365.1163 | I18: =C18*G18 -> 6365.1163 | J18: =INDEX($J$28:$J$50,MATCH(K18,$K$28:$K$50,0)) -> 110T | K18: RNW1101A2U | L18: =IF(ISERROR(VLOOKUP(K18,LG제품!$A$3:$C$271,2,0)),,VLOOKUP(K18,LG제품!$A$3:$C$271,2,0)) -> 11000 | M18: =IF(ISERROR(VLOOKUP(K18,LG제품!$A$3:$C$271,3,0)),,VLOOKUP(K18,LG제품!$A$3:$C$271,3,0)) -> 12400 | N18: 1 | O18: =L18*N18 -> 11000 | P18: =M18*N18 -> 12400
B19: 보건실 | C19: 65.2 | D19: 170 | E19: =D19 -> 170 | F19: =D19/0.86 -> 197.67442 | G19: =E19/0.86 -> 197.67442 | H19: =C19*F19 -> 12888.372 | I19: =C19*G19 -> 12888.372 | J19: =INDEX($J$28:$J$50,MATCH(K19,$K$28:$K$50,0)) -> 110T | K19: RNW1101A2U | L19: =IF(ISERROR(VLOOKUP(K19,LG제품!$A$3:$C$271,2,0)),,VLOOKUP(K19,LG제품!$A$3:$C$271,2,0)) -> 11000 | M19: =IF(ISERROR(VLOOKUP(K19,LG제품!$A$3:$C$271,3,0)),,VLOOKUP(K19,LG제품!$A$3:$C$271,3,0)) -> 12400 | N19: 1 | O19: =L19*N19 -> 11000 | P19: =M19*N19 -> 12400
B20: 합계 | N20: =SUM(N14:N19) -> 6 | O20: =SUM(O14:O19) -> 66000 | P20: =SUM(P14:P19) -> 74400
N21: =SUM(N20,N13,N7) -> 19 | U21: =SUM(U5:U20) -> 3
A22: ※ NOTE
A23: 1. 최종보정값은 배관길이,온도차,제상운전에 관한 보정계수 적용값이며, 보정계수는 장비 및 현장조건에 따라 달라짐.
A24: 2. 최종보정값은 실별 필요부하량을 만족해야함.
A25: 3. 실내/외기 조합비는 100%이내여야 함.
J27: 실내기 | Q27: 하이브리드 실외기 | U27: HP | V27: HP계
J28: 20C | K28: R-W0200C2S | L28: =SUMPRODUCT(($K$5:$K$20=K28)*($N$5:$N$20)) -> 0 | Q28: 24 | R28: GPHW241C1E1 | S28: =SUMPRODUCT(($R$5:$R$20=R28)*($U$5:$U$20)) -> 1 | U28: =MID(R28,5,2) -> 24 | V28: =U28*S28 -> 24
J29: 23C | K29: R-W0230C2S | L29: =SUMPRODUCT(($K$5:$K$20=K29)*($N$5:$N$20)) -> 0 | Q29: 26 | R29: GPHW261C1E2 | S29: =SUMPRODUCT(($R$5:$R$20=R29)*($U$5:$U$20)) -> 0 | U29: =MID(R29,5,2) -> 26 | V29: =U29*S29 -> 0
J30: 32C | K30: R-W0320C2S | L30: =SUMPRODUCT(($K$5:$K$20=K30)*($N$5:$N$20)) -> 0 | Q30: 28 | R30: GPHW281C1E3 | S30: =SUMPRODUCT(($R$5:$R$20=R30)*($U$5:$U$20)) -> 0 | U30: =MID(R30,5,2) -> 28 | V30: =U30*S30 -> 0
J31: 40C | K31: R-W0400C2S | L31: =SUMPRODUCT(($K$5:$K$20=K31)*($N$5:$N$20)) -> 0 | Q31: 30 | R31: GPHW301C2E2 | S31: =SUMPRODUCT(($R$5:$R$20=R31)*($U$5:$U$20)) -> 0 | U31: =MID(R31,5,2) -> 30 | V31: =U31*S31 -> 0
J32: 52C | K32: R-W0520C2S | L32: =SUMPRODUCT(($K$5:$K$20=K32)*($N$5:$N$20)) -> 0 | Q32: 32 | R32: GPHW321C2E3 | S32: =SUMPRODUCT(($R$5:$R$20=R32)*($U$5:$U$20)) -> 0 | U32: =MID(R32,5,2) -> 32 | V32: =U32*S32 -> 0
J33: 60C | K33: R-W0600C2S | L33: =SUMPRODUCT(($K$5:$K$20=K33)*($N$5:$N$20)) -> 0 | Q33: 35 | R33: GPHW351C3E2 | S33: =SUMPRODUCT(($R$5:$R$20=R33)*($U$5:$U$20)) -> 0 | U33: =MID(R33,5,2) -> 35 | V33: =U33*S33 -> 0
J34: 72C | K34: R-W0720C2S | L34: =SUMPRODUCT(($K$5:$K$20=K34)*($N$5:$N$20)) -> 0 | Q34: 37 | R34: GPHW371C3E3 | S34: =SUMPRODUCT(($R$5:$R$20=R34)*($U$5:$U$20)) -> 0 | U34: =MID(R34,5,2) -> 37 | V34: =U34*S34 -> 0
J35: 52G | K35: R-W0521G2S | L35: =SUMPRODUCT(($K$5:$K$20=K35)*($N$5:$N$20)) -> 0 | Q35: 44 | R35: GPHW441C4E5 | S35: =SUMPRODUCT(($R$5:$R$20=R35)*($U$5:$U$20)) -> 0 | U35: =MID(R35,5,2) -> 44 | V35: =U35*S35 -> 0
J36: 60G | K36: R-W0601G2S | L36: =SUMPRODUCT(($K$5:$K$20=K36)*($N$5:$N$20)) -> 0 | Q36: 46 | R36: GPHW461C5E5 | S36: =SUMPRODUCT(($R$5:$R$20=R36)*($U$5:$U$20)) -> 0 | U36: =MID(R36,5,2) -> 46 | V36: =U36*S36 -> 0
J37: 72G | K37: R-W0721G2S | L37: =SUMPRODUCT(($K$5:$K$20=K37)*($N$5:$N$20)) -> 0 | Q37: 46 | R37: GPHW461C4E6 | S37: =SUMPRODUCT(($R$5:$R$20=R37)*($U$5:$U$20)) -> 1 | U37: =MID(R37,5,2) -> 46 | V37: =U37*S37 -> 46
J38: 23M | K38: R-W0230M2S | L38: =SUMPRODUCT(($K$5:$K$20=K38)*($N$5:$N$20)) -> 0 | Q38: 48 | R38: GPHW481C6E5 | S38: =SUMPRODUCT(($R$5:$R$20=R38)*($U$5:$U$20)) -> 1 | U38: =MID(R38,5,2) -> 48 | V38: =U38*S38 -> 48
J39: 32M | K39: R-W0320M2S | L39: =SUMPRODUCT(($K$5:$K$20=K39)*($N$5:$N$20)) -> 0 | Q39: 48 | R39: GPHW481C5E6 | S39: =SUMPRODUCT(($R$5:$R$20=R39)*($U$5:$U$20)) -> 0 | U39: =MID(R39,5,2) -> 48 | V39: =U39*S39 -> 0
... J43: 52T | K43: RNW0521A2U | L43: =SUMPRODUCT(($K$5:$K$20=K43)*($N$5:$N$20)) -> 0 | Q43: 52 | R43: GPHW521C6E7 | S43: =SUMPRODUCT(($R$5:$R$20=R43)*($U$5:$U$20)) -> 0 | U43: =MID(R43,5,2) -> 52 | V43: =U43*S43 -> 0
J44: 60T | K44: RNW0601A2U | L44: =SUMPRODUCT(($K$5:$K$20=K44)*($N$5:$N$20)) -> 0 | Q44: 합계 | S44: =SUM(S28:S43) -> 3 | U44: 계 | V44: =SUM(V28:V43) -> 118
...

Sheet Mini, Multi V S
A1: ■ 상업용/주거용 냉난방 장비선정표
A3: 층 별 | B3: 실 명 | C3: 면 적 | D3: 단위부하(kcal/h.㎡) | F3: 단위부하(w) | H3: 필요부하량(W) | J3: 장비 번호 | K3: 실내기 모델명 | L3: 냉방용량 | M3: 난방용량 | N3: 대수 | O3: 총냉방용량 | P3: 총난방용량 | Q3: 장비 번호 | R3: 실외기 모델명 | S3: 실외기냉방용량 | T3: 실외기난방용량 | U3: 대수 | V3: 조합비 | W3: 비 고
C4: ㎡ | D4: 냉방 | E4: 난방 | F4: 냉방 | G4: 난방 | H4: 냉방 | I4: 난방 | L4: (W) | M4: (W) | N4: (대) | O4: (W) | P4: (W) | S4: (W) | T4: (W) | U4: (대)
A5: 1층 | B5: 발전기실 | C5: 14.276 | D5: 130 | E5: =D5 -> 130 | F5: =D5/0.86 -> 151.16279 | G5: =E5/0.86 -> 151.16279 | H5: =C5*F5 -> 2158 | I5: =C5*G5 -> 2158 | J5: =INDEX($J$20:$J$55,MATCH(K5,$K$20:$K$55,0)) -> 20C | K5: RNW0200C2S | L5: =IF(ISERROR(VLOOKUP(K5,LG제품!$A$3:$C$271,2,0)),,VLOOKUP(K5,LG제품!$A$3:$C$271,2,0)) -> 2000 | M5: =IF(ISERROR(VLOOKUP(K5,LG제품!$A$3:$C$271,3,0)),,VLOOKUP(K5,LG제품!$A$3:$C$271,3,0)) -> 2200 | N5: 1 | O5: =L5*N5 -> 2000 | P5: =M5*N5 -> 2200 | Q5: =INDEX($Q$20:$Q$42,MATCH(R5,$R$20:$R$42,0)) -> 10 | R5: RPUW101S9S | S5: =IF(ISERROR(VLOOKUP(R5,LG제품!$I$3:$K$39,2,0)),,VLOOKUP(R5,LG제품!$I$3:$K$39,2,0)) -> 28000 | T5: =IF(ISERROR(VLOOKUP(R5,LG제품!$I$3:$K$39,3,0)),,VLOOKUP(R5,LG제품!$I$3:$K$39,3,0)) -> 31500 | U5: 1 | V5: =O9/S5 -> 0.71428571
B6: 감시실 | C6: 29.022 | D6: 180 | E6: =D6 -> 180 | F6: =D6/0.86 -> 209.30233 | G6: =E6/0.86 -> 209.30233 | H6: =C6*F6 -> 6074.3721 | I6: =C6*G6 -> 6074.3721 | J6: =INDEX($J$20:$J$55,MATCH(K6,$K$20:$K$55,0)) -> 60T | K6: RNW0601A2U | L6: =IF(ISERROR(VLOOKUP(K6,LG제품!$A$3:$C$271,2,0)),,VLOOKUP(K6,LG제품!$A$3:$C$271,2,0)) -> 6000 | M6: =IF(ISERROR(VLOOKUP(K6,LG제품!$A$3:$C$271,3,0)),,VLOOKUP(K6,LG제품!$A$3:$C$271,3,0)) -> 6800 | N6: 1 | O6: =L6*N6 -> 6000 | P6: =M6*N6 -> 6800
B7: 관리사무실-2 | C7: 40 | D7: 150 | E7: =D7 -> 150 | F7: =D7/0.86 -> 174.4186 | G7: =E7/0.86 -> 174.4186 | H7: =C7*F7 -> 6976.7442 | I7: =C7*G7 -> 6976.7442 | J7: =INDEX($J$20:$J$55,MATCH(K7,$K$20:$K$55,0)) -> 60T | K7: RNW0601A2U | L7: =IF(ISERROR(VLOOKUP(K7,LG제품!$A$3:$C$271,2,0)),,VLOOKUP(K7,LG제품!$A$3:$C$271,2,0)) -> 6000 | M7: =IF(ISERROR(VLOOKUP(K7,LG제품!$A$3:$C$271,3,0)),,VLOOKUP(K7,LG제품!$A$3:$C$271,3,0)) -> 6800 | N7: 1 | O7: =L7*N7 -> 6000 | P7: =M7*N7 -> 6800
B8: 방재실 | C8: 50 | D8: 180 | E8: =D8 -> 180 | F8: =D8/0.86 -> 209.30233 | G8: =E8/0.86 -> 209.30233 | H8: =C8*F8 -> 10465.116 | I8: =C8*G8 -> 10465.116 | J8: =INDEX($J$20:$J$55,MATCH(K8,$K$20:$K$55,0)) -> 60T | K8: RNW0601A2U | L8: =IF(ISERROR(VLOOKUP(K8,LG제품!$A$3:$C$271,2,0)),,VLOOKUP(K8,LG제품!$A$3:$C$271,2,0)) -> 6000 | M8: =IF(ISERROR(VLOOKUP(K8,LG제품!$A$3:$C$271,3,0)),,VLOOKUP(K8,LG제품!$A$3:$C$271,3,0)) -> 6800 | N8: 1 | O8: =L8*N8 -> 6000 | P8: =M8*N8 -> 6800
B9: 합계 | N9: =SUM(N5:N8) -> 4 | O9: =SUM(O5:O8) -> 20000 | P9: =SUM(P5:P8) -> 22600
A10: 2층 | B10: 룸 | C10: 30 | D10: 150 | E10: =D10 -> 150 | F10: =D10/0.86 -> 174.4186 | G10: =E10/0.86 -> 174.4186 | H10: =C10*F10 -> 5232.5581 | I10: =C10*G10 -> 5232.5581 | J10: =INDEX($J$20:$J$55,MATCH(K10,$K$20:$K$55,0)) -> 60T | K10: RNW0601A2U | L10: =IF(ISERROR(VLOOKUP(K10,LG제품!$A$3:$C$271,2,0)),,VLOOKUP(K10,LG제품!$A$3:$C$271,2,0)) -> 6000 | M10: =IF(ISERROR(VLOOKUP(K10,LG제품!$A$3:$C$271,3,0)),,VLOOKUP(K10,LG제품!$A$3:$C$271,3,0)) -> 6800 | N10: 1 | O10: =L10*N10 -> 6000 | P10: =M10*N10 -> 6800 | Q10: =INDEX($Q$20:$Q$42,MATCH(R10,$R$20:$R$42,0)) -> Q8 | R10: RPUQ0802S9R | S10: =IF(ISERROR(VLOOKUP(R10,LG제품!$I$3:$K$39,2,0)),,VLOOKUP(R10,LG제품!$I$3:$K$39,2,0)) -> 23000 | T10: =IF(ISERROR(VLOOKUP(R10,LG제품!$I$3:$K$39,3,0)),,VLOOKUP(R10,LG제품!$I$3:$K$39,3,0)) -> 0 | U10: 1 | V10: =O14/S10 -> 1.0434783
A11: 3층 | B11: 룸 | C11: 30 | D11: 150 | E11: =D11 -> 150 | F11: =D11/0.86 -> 174.4186 | G11: =E11/0.86 -> 174.4186 | H11: =C11*F11 -> 5232.5581 | I11: =C11*G11 -> 5232.5581 | J11: =INDEX($J$20:$J$55,MATCH(K11,$K$20:$K$55,0)) -> 60T | K11: RNW0601A2U | L11: =IF(ISERROR(VLOOKUP(K11,LG제품!$A$3:$C$271,2,0)),,VLOOKUP(K11,LG제품!$A$3:$C$271,2,0)) -> 6000 | M11: =IF(ISERROR(VLOOKUP(K11,LG제품!$A$3:$C$271,3,0)),,VLOOKUP(K11,LG제품!$A$3:$C$271,3,0)) -> 6800 | N11: 1 | O11: =L11*N11 -> 6000 | P11: =M11*N11 -> 6800
A12: 4층 | B12: 룸 | C12: 30 | D12: 150 | E12: =D12 -> 150 | F12: =D12/0.86 -> 174.4186 | G12: =E12/0.86 -> 174.4186 | H12: =C12*F12 -> 5232.5581 | I12: =C12*G12 -> 5232.5581 | J12: =INDEX($J$20:$J$55,MATCH(K12,$K$20:$K$55,0)) -> 60T | K12: RNW0601A2U | L12: =IF(ISERROR(VLOOKUP(K12,LG제품!$A$3:$C$271,2,0)),,VLOOKUP(K12,LG제품!$A$3:$C$271,2,0)) -> 6000 | M12: =IF(ISERROR(VLOOKUP(K12,LG제품!$A$3:$C$271,3,0)),,VLOOKUP(K12,LG제품!$A$3:$C$271,3,0)) -> 6800 | N12: 1 | O12: =L12*N12 -> 6000 | P12: =M12*N12 -> 6800
A13: 5층 | B13: 룸 | C13: 30 | D13: 150 | E13: =D13 -> 150 | F13: =D13/0.86 -> 174.4186 | G13: =E13/0.86 -> 174.4186 | H13: =C13*F13 -> 5232.5581 | I13: =C13*G13 -> 5232.5581 | J13: =INDEX($J$20:$J$55,MATCH(K13,$K$20:$K$55,0)) -> 60T | K13: RNW0601A2U | L13: =IF(ISERROR(VLOOKUP(K13,LG제품!$A$3:$C$271,2,0)),,VLOOKUP(K13,LG제품!$A$3:$C$271,2,0)) -> 6000 | M13: =IF(ISERROR(VLOOKUP(K13,LG제품!$A$3:$C$271,3,0)),,VLOOKUP(K13,LG제품!$A$3:$C$271,3,0)) -> 6800 | N13: 1 | O13: =L13*N13 -> 6000 | P13: =M13*N13 -> 6800
B14: 합계 | N14: =SUM(N10:N13) -> 4 | O14: =SUM(O10:O13) -> 24000 | P14: =SUM(P10:P13) -> 27200
N15: =SUM(N14,N9) -> 8 | U15: =SUM(U5:U14) -> 2
J19: 상업용 | Q19: 상업용 | U19: HP | V19: HP계
J20: 20C | K20: RNW0200C2S | L20: =SUMPRODUCT(($K$5:$K$16=K20)*($N$5:$N$16)) -> 1 | Q20: Q4 | R20: RPUQ041S2S | S20: =SUMPRODUCT(($R$5:$R$15=R20)*($U$5:$U$15)) -> 0 | U20: =MID(R20,5,2) -> 04 | V20: =U20*S20 -> 0
J21: 23C | K21: RNW0230C2S | L21: =SUMPRODUCT(($K$5:$K$16=K21)*($N$5:$N$16)) -> 0 | Q21: Q5 | R21: RPUQ051S2S | S21: =SUMPRODUCT(($R$5:$R$15=R21)*($U$5:$U$15)) -> 0 | U21: =MID(R21,5,2) -> 05 | V21: =U21*S21 -> 0
J22: 32C | K22: RNW0320C2S | L22: =SUMPRODUCT(($K$5:$K$16=K22)*($N$5:$N$16)) -> 0 | Q22: Q6 | R22: RPUQ061S2S | S22: =SUMPRODUCT(($R$5:$R$15=R22)*($U$5:$U$15)) -> 0 | U22: =MID(R22,5,2) -> 06 | V22: =U22*S22 -> 0
J23: 40C | K23: RNW0400C2S | L23: =SUMPRODUCT(($K$5:$K$16=K23)*($N$5:$N$16)) -> 0 | Q23: Q8 | R23: RPUQ081S9S | S23: =SUMPRODUCT(($R$5:$R$15=R23)*($U$5:$U$15)) -> 0 | U23: =MID(R23,5,2) -> 08 | V23: =U23*S23 -> 0
J24: 52C | K24: RNW0520C2S | L24: =SUMPRODUCT(($K$5:$K$16=K24)*($N$5:$N$16)) -> 0 | Q24: Q10 | R24: RPUQ101S9S | S24: =SUMPRODUCT(($R$5:$R$15=R24)*($U$5:$U$15)) -> 0 | U24: =MID(R24,5,2) -> 10 | V24: =U24*S24 -> 0
J25: 60C | K25: RNW0600C2S | L25: =SUMPRODUCT(($K$5:$K$16=K25)*($N$5:$N$16)) -> 0 | Q25: 4 | R25: RPUW042S2S | S25: =SUMPRODUCT(($R$5:$R$15=R25)*($U$5:$U$15)) -> 0 | U25: =MID(R25,5,2) -> 04 | V25: =U25*S25 -> 0
J26: 72C | K26: RNW0720C2S | L26: =SUMPRODUCT(($K$5:$K$16=K26)*($N$5:$N$16)) -> 0 | Q26: 5 | R26: RPUW052S2S | S26: =SUMPRODUCT(($R$5:$R$15=R26)*($U$5:$U$15)) -> 0 | U26: =MID(R26,5,2) -> 05 | V26: =U26*S26 -> 0
J27: 52G | K27: RNW0521G2S | L27: =SUMPRODUCT(($K$5:$K$16=K27)*($N$5:$N$16)) -> 0 | Q27: 6 | R27: RPUW062S2S | S27: =SUMPRODUCT(($R$5:$R$15=R27)*($U$5:$U$15)) -> 0 | U27: =MID(R27,5,2) -> 06 | V27: =U27*S27 -> 0
J28: 60G | K28: RNW0601G2S | L28: =SUMPRODUCT(($K$5:$K$16=K28)*($N$5:$N$16)) -> 0 | Q28: 4 | R28: RPUW041S9S | S28: =SUMPRODUCT(($R$5:$R$15=R28)*($U$5:$U$15)) -> 0 | U28: =MID(R28,5,2) -> 04 | V28: =U28*S28 -> 0
J29: 72G | K29: RNW0721G2S | L29: =SUMPRODUCT(($K$5:$K$16=K29)*($N$5:$N$16)) -> 0 | Q29: 5 | R29: RPUW051S9S | S29: =SUMPRODUCT(($R$5:$R$15=R29)*($U$5:$U$15)) -> 0 | U29: =MID(R29,5,2) -> 05 | V29: =U29*S29 -> 0
J30: 23M | K30: RNW0230M2S | L30: =SUMPRODUCT(($K$5:$K$16=K30)*($N$5:$N$16)) -> 0 | Q30: 6 | R30: RPUW061S9S | S30: =SUMPRODUCT(($R$5:$R$15=R30)*($U$5:$U$15)) -> 0 | U30: =MID(R30,5,2) -> 06 | V30: =U30*S30 -> 0
J31: 32M | K31: RNW0320M2S | L31: =SUMPRODUCT(($K$5:$K$16=K31)*($N$5:$N$16)) -> 0 | Q31: 8 | R31: RPUW081S9S | S31: =SUMPRODUCT(($R$5:$R$15=R31)*($U$5:$U$15)) -> 0 | U31: =MID(R31,5,2) -> 08 | V31: =U31*S31 -> 0
J32: 40M | K32: RNW0400M2S | L32: =SUMPRODUCT(($K$5:$K$16=K32)*($N$5:$N$16)) -> 0 | Q32: 10 | R32: RPUW101S9S | S32: =SUMPRODUCT(($R$5:$R$15=R32)*($U$5:$U$15)) -> 1 | U32: =MID(R32,5,2) -> 10 | V32: =U32*S32 -> 10
J33: 52M | K33: RNW0520M2S | L33: =SUMPRODUCT(($K$5:$K$16=K33)*($N$5:$N$16)) -> 0 | Q33: 12 | R33: RPUW121S9S | S33: =SUMPRODUCT(($R$5:$R$15=R33)*($U$5:$U$15)) -> 0 | U33: =MID(R33,5,2) -> 12 | V33: =U33*S33 -> 0
J34: 40T | K34: RNW0401A2U | L34: =SUMPRODUCT(($K$5:$K$16=K34)*($N$5:$N$16)) -> 0 | Q34: 합계 | S34: =SUM(S20:S33) -> 1
J35: 52T | K35: RNW0521A2U | L35: =SUMPRODUCT(($K$5:$K$16=K35)*($N$5:$N$16)) -> 0 | Q35: 주거용
J36: 60T | K36: RNW0601A2U | L36: =SUMPRODUCT(($K$5:$K$16=K36)*($N$5:$N$16)) -> 7 | Q36: Q2.5 | R36: RPUQ0255A2R | S36: =SUMPRODUCT(($R$5:$R$15=R36)*($U$5:$U$15)) -> 0 | U36: =MID(R36,5,2) -> 02 | V36: =U36*S36 -> 0
J37: 72T | K37: RNW0721A2U | L37: =SUMPRODUCT(($K$5:$K$16=K37)*($N$5:$N$16)) -> 0 | Q37: Q3 | R37: RPUQ0305A2R | S37: =SUMPRODUCT(($R$5:$R$15=R37)*($U$5:$U$15)) -> 0 | U37: =MID(R37,5,2) -> 03 | V37: =U37*S37 -> 0
J38: 83T | K38: RNW0831A2U | L38: =SUMPRODUCT(($K$5:$K$16=K38)*($N$5:$N$16)) -> 0 | Q38: Q4 | R38: RPUQ0405B2R | S38: =SUMPRODUCT(($R$5:$R$15=R38)*($U$5:$U$15)) -> 0 | U38: =MID(R38,5,2) -> 04 | V38: =U38*S38 -> 0
J39: 100T | K39: RNW1001A2U | L39: =SUMPRODUCT(($K$5:$K$16=K39)*($N$5:$N$16)) -> 0 | Q39: Q5 | R39: RPUQ0506S2R | S39: =SUMPRODUCT(($R$5:$R$15=R39)*($U$5:$U$15)) -> 0 | U39: =MID(R39,5,2) -> 05 | V39: =U39*S39 -> 0
J40: 110T | K40: RNW1101A2U | L40: =SUMPRODUCT(($K$5:$K$16=K40)*($N$5:$N$16)) -> 0 | Q40: Q6 | R40: RPUQ0606S2R | S40: =SUMPRODUCT(($R$5:$R$15=R40)*($U$5:$U$15)) -> 0 | U40: =MID(R40,5,2) -> 06 | V40: =U40*S40 -> 0
J41: 130T | K41: RNW1301A2U | L41: =SUMPRODUCT(($K$5:$K$16=K41)*($N$5:$N$16)) -> 0 | Q41: Q8 | R41: RPUQ0802S9R | S41: =SUMPRODUCT(($R$5:$R$15=R41)*($U$5:$U$15)) -> 1 | U41: =MID(R41,5,2) -> 08 | V41: =U41*S41 -> 8
J42: 145T | K42: RNW1451A2U | L42: =SUMPRODUCT(($K$5:$K$16=K42)*($N$5:$N$16)) -> 0 | Q42: Q10 | R42: RPUQ1002S9R | S42: =SUMPRODUCT(($R$5:$R$15=R42)*($U$5:$U$15)) -> 0 | U42: =MID(R42,5,2) -> 10 | V42: =U42*S42 -> 0
J43: 합계 | L43: =SUM(L20:L42) -> 8 | Q43: 합계 | S43: =SUM(S36:S42) -> 1 | U43: =MID(#REF!,5,2) -> #REF! | V43: =U43*#REF! -> #REF!
J44: 주거용 | U44: 계 | V44: =SUM(V19:V43) -> #REF!
...

Sheet 수냉식
A1: ■ 수냉식 냉난방 장비선정표
W2: ※ 본 도면의 부하/장비선정은 특정사례로 현장조건에 따라 달라 짐
A3: 층 별 | B3: 실 명 | C3: 면 적 | D3: 단위부하(kcal/h.㎡) | F3: 단위부하(w) | H3: 필요부하량(W) | J3: 장비 번호 | K3: 실내기 모델명 | L3: 냉방용량 | M3: 난방용량 | N3: 대수 | O3: 총냉방용량 | P3: 총난방용량 | Q3: 장비 번호 | R3: 실외기 모델명 | S3: 실외기냉방용량 | T3: 실외기난방용량 | U3: 대수 | V3: 조합비 | W3: 비 고
C4: ㎡ | D4: 냉방 | E4: 난방 | F4: 냉방 | G4: 난방 | H4: 냉방 | I4: 난방 | L4: (W) | M4: (W) | N4: (대) | O4: (W) | P4: (W) | S4: (W) | T4: (W) | U4: (대)
A5: 지하1층 | B5: 시청각실 | C5: 20 | D5: 140 | E5: =D5 -> 140 | F5: =D5/0.86 -> 162.7907 | G5: =E5/0.86 -> 162.7907 | H5: =C5*F5 -> 3255.814 | I5: =C5*G5 -> 3255.814 | J5: =INDEX($J$27:$J$49,MATCH(K5,$K$27:$K$49,0)) -> 40C | K5: RNW0400C2S | L5: =IF(ISERROR(VLOOKUP(K5,LG제품!$A$3:$C$271,2,0)),,VLOOKUP(K5,LG제품!$A$3:$C$271,2,0)) -> 4000 | M5: =IF(ISERROR(VLOOKUP(K5,LG제품!$A$3:$C$271,3,0)),,VLOOKUP(K5,LG제품!$A$3:$C$271,3,0)) -> 4500 | N5: 3 | O5: =L5*N5 -> 12000 | P5: =M5*N5 -> 13500 | Q5: =SUMIF($R$26:$R$45,$R5,$Q$26:$Q$45) -> 18 | R5: RG-W181C9C | S5: =IF(ISERROR(VLOOKUP(R5,LG제품!$I$43:$K$64,2,0)),,VLOOKUP(R5,LG제품!$I$43:$K$64,2,0)) -> 50400 | T5: =IF(ISERROR(VLOOKUP(R5,LG제품!$I$43:$K$64,3,0)),,VLOOKUP(R5,LG제품!$I$43:$K$64,3,0)) -> 56700 | U5: 1 | V5: =O7/S5 -> 0.35714286
B6: 준비실(위) | C6: 5.4 | D6: 150 | E6: =D6 -> 150 | F6: =D6/0.86 -> 174.4186 | G6: =E6/0.86 -> 174.4186 | H6: =C6*F6 -> 941.86047 | I6: =C6*G6 -> 941.86047 | J6: =INDEX($J$27:$J$49,MATCH(K6,$K$27:$K$49,0)) -> 20C | K6: RNW0200C2S | L6: =IF(ISERROR(VLOOKUP(K6,LG제품!$A$3:$C$271,2,0)),,VLOOKUP(K6,LG제품!$A$3:$C$271,2,0)) -> 2000 | M6: =IF(ISERROR(VLOOKUP(K6,LG제품!$A$3:$C$271,3,0)),,VLOOKUP(K6,LG제품!$A$3:$C$271,3,0)) -> 2200 | N6: 3 | O6: =L6*N6 -> 6000 | P6: =M6*N6 -> 6600
B7: 합계 | N7: =SUM(N5:N6) -> 6 | O7: =SUM(O5:O6) -> 18000 | P7: =SUM(P5:P6) -> 20100
A8: 지상1층 | B8: 미술실 | C8: 97.5 | D8: 180 | E8: =D8 -> 180 | F8: =D8/0.86 -> 209.30233 | G8: =E8/0.86 -> 209.30233 | H8: =C8*F8 -> 20406.977 | I8: =C8*G8 -> 20406.977 | J8: =INDEX($J$27:$J$49,MATCH(K8,$K$27:$K$49,0)) -> 60T | K8: RNW0601A2U | L8: =IF(ISERROR(VLOOKUP(K8,LG제품!$A$3:$C$271,2,0)),,VLOOKUP(K8,LG제품!$A$3:$C$271,2,0)) -> 6000 | M8: =IF(ISERROR(VLOOKUP(K8,LG제품!$A$3:$C$271,3,0)),,VLOOKUP(K8,LG제품!$A$3:$C$271,3,0)) -> 6800 | N8: 2 | O8: =L8*N8 -> 12000 | P8: =M8*N8 -> 13600 | Q8: =SUMIF($R$26:$R$45,$R8,$Q$26:$Q$45) -> 18 | R8: RG-W181C9C | S8: =IF(ISERROR(VLOOKUP(R8,LG제품!$I$43:$K$64,2,0)),,VLOOKUP(R8,LG제품!$I$43:$K$64,2,0)) -> 50400 | T8: =IF(ISERROR(VLOOKUP(R8,LG제품!$I$43:$K$64,3,0)),,VLOOKUP(R8,LG제품!$I$43:$K$64,3,0)) -> 56700 | U8: 1 | V8: =O13/S8 -> 0.83333333
B9: 준비실 | C9: 30.6 | D9: 150 | E9: =D9 -> 150 | F9: =D9/0.86 -> 174.4186 | G9: =E9/0.86 -> 174.4186 | H9: =C9*F9 -> 5337.2093 | I9: =C9*G9 -> 5337.2093 | J9: =INDEX($J$27:$J$49,MATCH(K9,$K$27:$K$49,0)) -> 60T | K9: RNW0601A2U | L9: =IF(ISERROR(VLOOKUP(K9,LG제품!$A$3:$C$271,2,0)),,VLOOKUP(K9,LG제품!$A$3:$C$271,2,0)) -> 6000 | M9: =IF(ISERROR(VLOOKUP(K9,LG제품!$A$3:$C$271,3,0)),,VLOOKUP(K9,LG제품!$A$3:$C$271,3,0)) -> 6800 | N9: 1 | O9: =L9*N9 -> 6000 | P9: =M9*N9 -> 6800
B10: 준비실 | C10: 27 | D10: 150 | E10: =D10 -> 150 | F10: =D10/0.86 -> 174.4186 | G10: =E10/0.86 -> 174.4186 | H10: =C10*F10 -> 4709.3023 | I10: =C10*G10 -> 4709.3023 | J10: =INDEX($J$27:$J$49,MATCH(K10,$K$27:$K$49,0)) -> 60T | K10: RNW0601A2U | L10: =IF(ISERROR(VLOOKUP(K10,LG제품!$A$3:$C$271,2,0)),,VLOOKUP(K10,LG제품!$A$3:$C$271,2,0)) -> 6000 | M10: =IF(ISERROR(VLOOKUP(K10,LG제품!$A$3:$C$271,3,0)),,VLOOKUP(K10,LG제품!$A$3:$C$271,3,0)) -> 6800 | N10: 1 | O10: =L10*N10 -> 6000 | P10: =M10*N10 -> 6800
B11: 기술실 | C11: 99 | D11: 180 | E11: =D11 -> 180 | F11: =D11/0.86 -> 209.30233 | G11: =E11/0.86 -> 209.30233 | H11: =C11*F11 -> 20720.93 | I11: =C11*G11 -> 20720.93 | J11: =INDEX($J$27:$J$49,MATCH(K11,$K$27:$K$49,0)) -> 60T | K11: RNW0601A2U | L11: =IF(ISERROR(VLOOKUP(K11,LG제품!$A$3:$C$271,2,0)),,VLOOKUP(K11,LG제품!$A$3:$C$271,2,0)) -> 6000 | M11: =IF(ISERROR(VLOOKUP(K11,LG제품!$A$3:$C$271,3,0)),,VLOOKUP(K11,LG제품!$A$3:$C$271,3,0)) -> 6800 | N11: 2 | O11: =L11*N11 -> 12000 | P11: =M11*N11 -> 13600
B12: 시설관리실 | C12: 22.2 | D12: 150 | E12: =D12 -> 150 | F12: =D12/0.86 -> 174.4186 | G12: =E12/0.86 -> 174.4186 | H12: =C12*F12 -> 3872.093 | I12: =C12*G12 -> 3872.093 | J12: =INDEX($J$27:$J$49,MATCH(K12,$K$27:$K$49,0)) -> 60T | K12: RNW0601A2U | L12: =IF(ISERROR(VLOOKUP(K12,LG제품!$A$3:$C$271,2,0)),,VLOOKUP(K12,LG제품!$A$3:$C$271,2,0)) -> 6000 | M12: =IF(ISERROR(VLOOKUP(K12,LG제품!$A$3:$C$271,3,0)),,VLOOKUP(K12,LG제품!$A$3:$C$271,3,0)) -> 6800 | N12: 1 | O12: =L12*N12 -> 6000 | P12: =M12*N12 -> 6800
B13: 합계 | N13: =SUM(N8:N12) -> 7 | O13: =SUM(O8:O12) -> 42000 | P13: =SUM(P8:P12) -> 47600
B14: 행정실 | C14: 64.8 | D14: 180 | E14: =D14 -> 180 | F14: =D14/0.86 -> 209.30233 | G14: =E14/0.86 -> 209.30233 | H14: =C14*F14 -> 13562.791 | I14: =C14*G14 -> 13562.791 | J14: =INDEX($J$27:$J$49,MATCH(K14,$K$27:$K$49,0)) -> 60T | K14: RNW0601A2U | L14: =IF(ISERROR(VLOOKUP(K14,LG제품!$A$3:$C$271,2,0)),,VLOOKUP(K14,LG제품!$A$3:$C$271,2,0)) -> 6000 | M14: =IF(ISERROR(VLOOKUP(K14,LG제품!$A$3:$C$271,3,0)),,VLOOKUP(K14,LG제품!$A$3:$C$271,3,0)) -> 6800 | N14: 1 | O14: =L14*N14 -> 6000 | P14: =M14*N14 -> 6800 | Q14: =SUMIF($R$26:$R$45,$R14,$Q$26:$Q$45) -> 12 | R14: RGUW121C9C | S14: =IF(ISERROR(VLOOKUP(R14,LG제품!$I$43:$K$64,2,0)),,VLOOKUP(R14,LG제품!$I$43:$K$64,2,0)) -> 33600 | T14: =IF(ISERROR(VLOOKUP(R14,LG제품!$I$43:$K$64,3,0)),,VLOOKUP(R14,LG제품!$I$43:$K$64,3,0)) -> 37800 | U14: 1 | V14: =O19/S14 -> 0.89285714
B15: 문서고 | C15: 16.9 | D15: 150 | E15: =D15 -> 150 | F15: =D15/0.86 -> 174.4186 | G15: =E15/0.86 -> 174.4186 | H15: =C15*F15 -> 2947.6744 | I15: =C15*G15 -> 2947.6744 | J15: =INDEX($J$27:$J$49,MATCH(K15,$K$27:$K$49,0)) -> 60T | K15: RNW0601A2U | L15: =IF(ISERROR(VLOOKUP(K15,LG제품!$A$3:$C$271,2,0)),,VLOOKUP(K15,LG제품!$A$3:$C$271,2,0)) -> 6000 | M15: =IF(ISERROR(VLOOKUP(K15,LG제품!$A$3:$C$271,3,0)),,VLOOKUP(K15,LG제품!$A$3:$C$271,3,0)) -> 6800 | N15: 1 | O15: =L15*N15 -> 6000 | P15: =M15*N15 -> 6800
